Workbook

Sheet Munition
A1: Folder | B1: Munition | C1: Type de munition | D1: Calibre | E1: type | F1: Masse (g) | G1: Diamètre (mm) | H1: Coeff, de traînée (Cd​) | I1: Rho (kg/m³) | J1: indice perforation | K1: Longueur Canon standard (pouces) | L1: vitesse (m/s) | M1: poids munition | N1: Surface (m2) | O1: Indice de freinage (1/m) | P1: Densité Sect. (kg/m²)
A2: Munition\5,45x39\BO | B2: 5,45 M74 | C2: bullet | D2: 5,45x39 | E2: BO | F2: 3.43 | G2: 5.45 | H2: 0.25 | I2: 1.225 | J2: 1 | K2: 16 | L2: 900 | M2: 10.5 | N2: =PI()*G2^2/4000000 -> 2.3328289e-05 | O2: =0.5 * N2 * H2 * I2 -> 3.5721442e-06 | P2: =(F2/1000) / ((PI() * (G2/1000)^2) / 4) -> 147.03179
A3: Munition\5,45x39\AP | B3: 5,45 7N22 | C3: bullet | D3: 5,45x39 | E3: AP | F3: 4.1 | G3: 5.45 | H3: 0.25 | I3: 1.225 | J3: 1.5 | K3: 16 | L3: 880 | M3: 11.2 | N3: =PI()*G3^2/4000000 -> 2.3328289e-05 | O3: =0.5 * N3 * H3 * I3 -> 3.5721442e-06 | P3: =(F3/1000) / ((PI() * (G3/1000)^2) / 4) -> 175.75228
A4: Munition\5,56x45\BO | B4: 5,56 M193 | C4: bullet | D4: 5,56x45 | E4: BO | F4: 3.56 | G4: 5.56 | H4: 0.25 | I4: 1.225 | J4: 1 | K4: 20 | L4: 878 | M4: 11.2 | N4: =PI()*G4^2/4000000 -> 2.4279485e-05 | O4: =0.5 * N4 * H4 * I4 -> 3.7177961e-06 | P4: =(F4/1000) / ((PI() * (G4/1000)^2) / 4) -> 146.62585
A5: Munition\5,56x45\BO | B5: 5,56 M855 | C5: bullet | D5: 5,56x45 | E5: BO | F5: 4 | G5: 5.56 | H5: 0.25 | I5: 1.225 | J5: 1 | K5: 20 | L5: 922 | M5: 12 | N5: =PI()*G5^2/4000000 -> 2.4279485e-05 | O5: =0.5 * N5 * H5 * I5 -> 3.7177961e-06 | P5: =(F5/1000) / ((PI() * (G5/1000)^2) / 4) -> 164.74814
A6: Munition\5,56x45\AP | B6: 5,56 M995 AP45 | C6: bullet | D6: 5,56x45 | E6: AP | F6: 4.5 | G6: 5.56 | H6: 0.25 | I6: 1.225 | J6: 1.5 | K6: 20 | L6: 1050 | M6: 13 | N6: =PI()*G6^2/4000000 -> 2.4279485e-05 | O6: =0.5 * N6 * H6 * I6 -> 3.7177961e-06 | P6: =(F6/1000) / ((PI() * (G6/1000)^2) / 4) -> 185.34166
A7: Munition\5,56x45\Sniper | B7: 5,56 M855A1 EPR | C7: bullet | D7: 5,56x45 | E7: Sniper | F7: 4 | G7: 5.56 | H7: 0.25 | I7: 1.225 | J7: 1 | K7: 20 | L7: 960 | M7: 12 | N7: =PI()*G7^2/4000000 -> 2.4279485e-05 | O7: =0.5 * N7 * H7 * I7 -> 3.7177961e-06 | P7: =(F7/1000) / ((PI() * (G7/1000)^2) / 4) -> 164.74814
A8: Munition\5,56x45\BO | B8: 5,56 Mk262 | C8: bullet | D8: 5,56x45 | E8: BO | F8: 5 | G8: 5.56 | H8: 0.25 | I8: 1.225 | J8: 1 | K8: 20 | L8: 892 | M8: 13 | N8: =PI()*G8^2/4000000 -> 2.4279485e-05 | O8: =0.5 * N8 * H8 * I8 -> 3.7177961e-06 | P8: =(F8/1000) / ((PI() * (G8/1000)^2) / 4) -> 205.93518
A9: Munition\5,56x15\BO | B9: .22 LR | C9: bullet | D9: 5,56x15 | E9: BO | F9: 2.59 | G9: 5.56 | H9: 0.35 | I9: 1.225 | J9: 1 | K9: 16 | L9: 345 | M9: 7 | N9: =PI()*G9^2/4000000 -> 2.4279485e-05 | O9: =0.5 * N9 * H9 * I9 -> 5.2049145e-06 | P9: =(F9/1000) / ((PI() * (G9/1000)^2) / 4) -> 106.67442
A10: Munition\5,56x15\Expansion | B10: .22 LR Creuse | C10: bullet | D10: 5,56x15 | E10: Expansion | F10: 2.07 | G10: 5.56 | H10: 0.35 | I10: 1.225 | J10: 1 | K10: 16 | L10: 330 | M10: 6.5 | N10: =PI()*G10^2/4000000 -> 2.4279485e-05 | O10: =0.5 * N10 * H10 * I10 -> 5.2049145e-06 | P10: =(F10/1000) / ((PI() * (G10/1000)^2) / 4) -> 85.257164
A11: Munition\5,56x15\Sniper | B11: .22 LR High Velocity | C11: bullet | D11: 5,56x15 | E11: Sniper | F11: 2.46 | G11: 5.56 | H11: 0.35 | I11: 1.225 | J11: 1 | K11: 16 | L11: 405 | M11: 7 | N11: =PI()*G11^2/4000000 -> 2.4279485e-05 | O11: =0.5 * N11 * H11 * I11 -> 5.2049145e-06 | P11: =(F11/1000) / ((PI() * (G11/1000)^2) / 4) -> 101.32011
A12: Munition\5,56x15\Sniper | B12: .22 LR Stinger | C12: bullet | D12: 5,56x15 | E12: Sniper | F12: 2.07 | G12: 5.56 | H12: 0.35 | I12: 1.225 | J12: 1 | K12: 16 | L12: 500 | M12: 6.5 | N12: =PI()*G12^2/4000000 -> 2.4279485e-05 | O12: =0.5 * N12 * H12 * I12 -> 5.2049145e-06 | P12: =(F12/1000) / ((PI() * (G12/1000)^2) / 4) -> 85.257164
A13: Munition\5,56x15\Expansion | B13: .22 Magnum | C13: bullet | D13: 5,56x15 | E13: Expansion | F13: 2.58 | G13: 5.56 | H13: 0.35 | I13: 1.225 | J13: 1 | K13: 16 | L13: 360 | M13: 7 | N13: =PI()*G13^2/4000000 -> 2.4279485e-05 | O13: =0.5 * N13 * H13 * I13 -> 5.2049145e-06 | P13: =(F13/1000) / ((PI() * (G13/1000)^2) / 4) -> 106.26255
... A54: Munition\9x29 | B54: .38 Spe Blindé | C54: bullet | D54: 9x29 | E54: AP | F54: 10.2 | G54: 9 | H54: 0.45 | I54: 1.225 | J54: 1.5 | K54: 4 | L54: 230 | M54: 20 | N54: =PI()*G54^2/4000000 -> 6.3617251e-05 | O54: =0.5 * N54 * H54 * I54 -> 1.7534505e-05 | P54: =(F54/1000) / ((PI() * (G54/1000)^2) / 4) -> 160.33387
A55: Munition\9x29 | B55: .38 Spe Tête creuse | C55: bullet | D55: 9x29 | E55: Expansion | F55: 7.1 | G55: 9 | H55: 0.45 | I55: 1.225 | J55: 1 | K55: 4 | L55: 390 | N55: =PI()*G55^2/4000000 -> 6.3617251e-05 | O55: =0.5 * N55 * H55 * I55 -> 1.7534505e-05 | P55: =(F55/1000) / ((PI() * (G55/1000)^2) / 4) -> 111.60495
A56: Munition\9x29 | B56: .38 Spe SJHP | C56: bullet | D56: 9x29 | F56: 8.06 | G56: 9 | H56: 0.45 | I56: 1.225 | J56: 1 | K56: 4 | L56: 308 | N56: =PI()*G56^2/4000000 -> 6.3617251e-05 | O56: =0.5 * N56 * H56 * I56 -> 1.7534505e-05 | P56: =(F56/1000) / ((PI() * (G56/1000)^2) / 4) -> 126.69519
A57: Munition\9x29 | B57: .38 Spe JHP | C57: bullet | D57: 9x29 | F57: 10.19 | G57: 9 | H57: 0.45 | I57: 1.225 | J57: 1 | K57: 4 | L57: 370 | N57: =PI()*G57^2/4000000 -> 6.3617251e-05 | O57: =0.5 * N57 * H57 * I57 -> 1.7534505e-05 | P57: =(F57/1000) / ((PI() * (G57/1000)^2) / 4) -> 160.17668
A58: Munition\9X29\JHP+P | B58: .38 Spe Grizzly | C58: bullet | D58: 9x29 | E58: JHP+P | F58: 10.24 | G58: 9 | H58: 0.45 | I58: 1.225 | J58: 1 | K58: 4 | L58: 297 | M58: 15.8 | N58: =PI()*G58^2/4000000 -> 6.3617251e-05 | O58: =0.5 * N58 * H58 * I58 -> 1.7534505e-05 | P58: =(F58/1000) / ((PI() * (G58/1000)^2) / 4) -> 160.96263
A59: Munition\9x29 | B59: .38 Spe +P+ | C59: bullet | D59: 9x29 | F59: 7.1 | G59: 9 | H59: 0.45 | I59: 1.225 | J59: 1 | K59: 4 | L59: 340 | M59: 11 | N59: =PI()*G59^2/4000000 -> 6.3617251e-05 | O59: =0.5 * N59 * H59 * I59 -> 1.7534505e-05 | P59: =(F59/1000) / ((PI() * (G59/1000)^2) / 4) -> 111.60495
A60: Munition\9x29 | B60: .38 Spe Super Police | C60: bullet | D60: 9x29 | F60: 13 | G60: 9 | H60: 0.45 | I60: 1.225 | J60: 1 | K60: 4 | L60: 205 | M60: 20 | N60: =PI()*G60^2/4000000 -> 6.3617251e-05 | O60: =0.5 * N60 * H60 * I60 -> 1.7534505e-05 | P60: =(F60/1000) / ((PI() * (G60/1000)^2) / 4) -> 204.34709
A61: Munition\9x29 | B61: .38 Cor-Bon FMJ | C61: bullet | D61: 9x29 | F61: 9.53 | G61: 9 | H61: 0.45 | I61: 1.225 | J61: 1 | K61: 4 | L61: 270 | M61: 14.7 | N61: =PI()*G61^2/4000000 -> 6.3617251e-05 | O61: =0.5 * N61 * H61 * I61 -> 1.7534505e-05 | P61: =(F61/1000) / ((PI() * (G61/1000)^2) / 4) -> 149.80213
A62: Munition\9x33\BO | B62: .357 Magnum | C62: bullet | D62: 9x33 | E62: BO | F62: 10.2 | G62: 9 | H62: 0.45 | I62: 1.225 | J62: 1 | K62: 6 | L62: 395 | M62: 17 | N62: =PI()*G62^2/4000000 -> 6.3617251e-05 | O62: =0.5 * N62 * H62 * I62 -> 1.7534505e-05 | P62: =(F62/1000) / ((PI() * (G62/1000)^2) / 4) -> 160.33387
A63: Munition\9x33\AP | B63: .357 Mag SB | C63: bullet | D63: 9x33 | E63: AP | F63: 8.1 | G63: 9 | H63: 0.45 | I63: 1.225 | J63: 1.5 | K63: 6 | L63: 395 | M63: 13.5 | N63: =PI()*G63^2/4000000 -> 6.3617251e-05 | O63: =0.5 * N63 * H63 * I63 -> 1.7534505e-05 | P63: =(F63/1000) / ((PI() * (G63/1000)^2) / 4) -> 127.32395
A64: Munition\9x33 | B64: .357 Mag Blindé | C64: bullet | D64: 9x33 | E64: AP | F64: 10.2 | G64: 9 | H64: 0.45 | I64: 1.225 | J64: 1.5 | K64: 6 | L64: 344 | N64: =PI()*G64^2/4000000 -> 6.3617251e-05 | O64: =0.5 * N64 * H64 * I64 -> 1.7534505e-05 | P64: =(F64/1000) / ((PI() * (G64/1000)^2) / 4) -> 160.33387
A65: Munition\9x33 | B65: .357 Mag TT creuse | C65: bullet | D65: 9x33 | E65: Expansion | F65: 7.1 | G65: 9 | H65: 0.45 | I65: 1.225 | J65: 1 | K65: 6 | L65: 368 | N65: =PI()*G65^2/4000000 -> 6.3617251e-05 | O65: =0.5 * N65 * H65 * I65 -> 1.7534505e-05 | P65: =(F65/1000) / ((PI() * (G65/1000)^2) / 4) -> 111.60495
A66: Munition\9x33 | B66: .357 Mag JHP 1 | C66: bullet | D66: 9x33 | F66: 8.06 | G66: 9 | H66: 0.45 | I66: 1.225 | J66: 1 | K66: 6 | L66: 435 | N66: =PI()*G66^2/4000000 -> 6.3617251e-05 | O66: =0.5 * N66 * H66 * I66 -> 1.7534505e-05 | P66: =(F66/1000) / ((PI() * (G66/1000)^2) / 4) -> 126.69519
A67: Munition\9x33 | B67: .357 Mag JHP 2 | C67: bullet | D67: 9x33 | F67: 7.1 | G67: 9 | H67: 0.45 | I67: 1.225 | J67: 1 | K67: 6 | L67: 465 | N67: =PI()*G67^2/4000000 -> 6.3617251e-05 | O67: =0.5 * N67 * H67 * I67 -> 1.7534505e-05 | P67: =(F67/1000) / ((PI() * (G67/1000)^2) / 4) -> 111.60495
A68: Munition\11,43x23\BO | B68: .44-40 | C68: bullet | D68: 11,43x23 | E68: BO | F68: 13 | G68: 11.43 | H68: 0.45 | I68: 1.225 | J68: 1 | K68: 5 | L68: 460 | M68: 23 | N68: =PI()*G68^2/4000000 -> 0.00010260826 | O68: =0.5 * N68 * H68 * I68 -> 2.8281403e-05 | P68: =(F68/1000) / ((PI() * (G68/1000)^2) / 4) -> 126.69545
A69: Munition\11,43x23\BO | B69: .44 Magnum | C69: bullet | D69: 11,43x23 | E69: BO | F69: 19 | G69: 11.43 | H69: 0.45 | I69: 1.225 | J69: 1 | K69: 5 | L69: 450 | M69: 31 | N69: =PI()*G69^2/4000000 -> 0.00010260826 | O69: =0.5 * N69 * H69 * I69 -> 2.8281403e-05 | P69: =(F69/1000) / ((PI() * (G69/1000)^2) / 4) -> 185.17027
A70: Munition\10,74x33\BO | B70: .44 AMP | C70: bullet | D70: 10,74x33 | E70: BO | F70: 19 | G70: 10.74 | H70: 0.4 | I70: 1.225 | J70: 1 | K70: 6 | L70: 500 | M70: 32 | N70: =PI()*G70^2/4000000 -> 9.0593793e-05 | O70: =0.5 * N70 * H70 * I70 -> 2.2195479e-05 | P70: =(F70/1000) / ((PI() * (G70/1000)^2) / 4) -> 209.72739
A71: Munition\10x22\BO | B71: .40 S&W | C71: bullet | D71: 10x22 | E71: BO | F71: 11.7 | G71: 10 | H71: 0.4 | I71: 1.225 | J71: 1 | K71: 4.2 | L71: 340 | M71: 21 | N71: =PI()*G71^2/4000000 -> 7.8539816e-05 | O71: =0.5 * N71 * H71 * I71 -> 1.9242255e-05 | P71: =(F71/1000) / ((PI() * (G71/1000)^2) / 4) -> 148.96903
A72: Munition\11,43x23\BO | B72: .45 ACP | C72: bullet | D72: 11,43x23 | E72: BO | F72: 14.84 | G72: 11.43 | H72: 0.45 | I72: 1.225 | J72: 1 | K72: 5 | L72: 285 | M72: 28 | N72: =PI()*G72^2/4000000 -> 0.00010260826 | O72: =0.5 * N72 * H72 * I72 -> 2.8281403e-05 | P72: =(F72/1000) / ((PI() * (G72/1000)^2) / 4) -> 144.62773
A73: Munition\11,43x23\AP | B73: .45 ACP Blindé | C73: bullet | D73: 11,43x23 | E73: AP | F73: 14.5 | G73: 11.43 | H73: 0.45 | I73: 1.225 | J73: 1.5 | K73: 5 | L73: 245 | N73: =PI()*G73^2/4000000 -> 0.00010260826 | O73: =0.5 * N73 * H73 * I73 -> 2.8281403e-05 | P73: =(F73/1000) / ((PI() * (G73/1000)^2) / 4) -> 141.31415
A74: Munition\11,43x23\Expansion | B74: .45 ACP TT creuse | C74: bullet | D74: 11,43x23 | E74: Expansion | F74: 12 | G74: 11.43 | H74: 0.45 | I74: 1.225 | J74: 1 | K74: 5 | L74: 266 | N74: =PI()*G74^2/4000000 -> 0.00010260826 | O74: =0.5 * N74 * H74 * I74 -> 2.8281403e-05 | P74: =(F74/1000) / ((PI() * (G74/1000)^2) / 4) -> 116.94964
A75: Munition\9x39\AP | B75: 9 SP 6 | C75: bullet | D75: 9x39 | E75: AP | F75: 16 | G75: 9.3 | H75: 0.35 | I75: 1.225 | J75: 1.5 | K75: 12 | L75: 310 | M75: 23 | N75: =PI()*G75^2/4000000 -> 6.7929087e-05 | O75: =0.5 * N75 * H75 * I75 -> 1.4562298e-05 | P75: =(F75/1000) / ((PI() * (G75/1000)^2) / 4) -> 235.53975
A76: Munition\9x39\BO | B76: 9 SP 5 | C76: bullet | D76: 9x39 | E76: BO | F76: 16.8 | G76: 9.3 | H76: 0.35 | I76: 1.225 | J76: 1 | K76: 12 | L76: 280 | M76: 23 | N76: =PI()*G76^2/4000000 -> 6.7929087e-05 | O76: =0.5 * N76 * H76 * I76 -> 1.4562298e-05 | P76: =(F76/1000) / ((PI() * (G76/1000)^2) / 4) -> 247.31673
A77: Munition\9x39\AP | B77: 9 BP | C77: bullet | D77: 9x39 | E77: AP | F77: 17.3 | G77: 9.3 | H77: 0.35 | I77: 1.225 | J77: 1.5 | K77: 12 | L77: 327 | M77: 23 | N77: =PI()*G77^2/4000000 -> 6.7929087e-05 | O77: =0.5 * N77 * H77 * I77 -> 1.4562298e-05 | P77: =(F77/1000) / ((PI() * (G77/1000)^2) / 4) -> 254.67735
A78: Munition\7.62x41\Subsonique | B78: 7,62 SP 4 | C78: bullet | D78: 7,62x41 | E78: Subsonique | F78: 9.3 | G78: 7.62 | H78: 0.28 | I78: 1.225 | J78: 1 | K78: 16 | L78: 265 | M78: 14 | N78: =PI()*G78^2/4000000 -> 4.5603673e-05 | O78: =0.5 * N78 * H78 * I78 -> 7.8210299e-06 | P78: =(F78/1000) / ((PI() * (G78/1000)^2) / 4) -> 203.93094
A79: Munition\9x19\AP | B79: 9 PBP | C79: bullet | D79: 9x19 | E79: AP | F79: 4.1 | G79: 9 | H79: 0.4 | I79: 1.225 | J79: 1.5 | K79: 4.5 | L79: 600 | M79: 8.2 | N79: =PI()*G79^2/4000000 -> 6.3617251e-05 | O79: =0.5 * N79 * H79 * I79 -> 1.5586227e-05 | P79: =(F79/1000) / ((PI() * (G79/1000)^2) / 4) -> 64.447928
A80: Munition\9x19\AP | B80: 7N21 | C80: bullet | D80: 9x19 | E80: AP | F80: 5.3 | G80: 9 | H80: 0.4 | I80: 1.225 | J80: 1.5 | K80: 4.5 | L80: 460 | N80: =PI()*G80^2/4000000 -> 6.3617251e-05 | O80: =0.5 * N80 * H80 * I80 -> 1.5586227e-05 | P80: =(F80/1000) / ((PI() * (G80/1000)^2) / 4) -> 83.310736
...

Sheet Weapon
A1: Folder | B1: Nom | C1: Sous-type d'arme | D1: Compétence associée | E1: Illustration | F1: Munition | G1: Calibre | H1: Poids à vide | I1: Canon (pouces) | J1: Range Short | K1: Range Med | L1: Range Long | M1: Range Extrem | N1: Recul C/C | O1: Recul Burst | P1: Chargeur | Q1: ROF mode | R1: ROF limited | S1: Longueur Canon standard (pouces) | T1: Vitesse initiale munition (m/s) | U1: Vitesse initiale arme (m/s) | V1: Masse Munition | W1: Energie Arme (joules) | X1: Densité Sect. munition (kg/m²) | Y1: ind. Perfo. Munition | Z1: Indice de freinage Munition (1/m) | AA1: Pénétr. Bouche (mm) | AB1: Pénétr. Courte (mm) | AC1: Pénétr. Moyenne (mm) | AD1: Pénétr. Longue (mm) | AE1: Pénétr. Extrême (mm) | AF1: Dégats | AG1: malus par tranche de blingage (courte) | AH1: malus par tranche de blingage (moyenne) | AI1: malus par tranche de blingage (longue) | AJ1: malus par tranche de blingage (extreme) | AK1: Année
A2: Armes à feu\Pistolet auto | B2: Tula Arms Plant - MSS Vul | C2: powder_projectiles | D2: powder_projectiles | F2: 7,62 SP 4 | G2: 7,62x42 | H2: 0.7 | I2: 16 | J2: 4 | K2: 8 | L2: 24 | M2: 48 | N2: 3 | P2: 6 | Q2: SA | R2: 1 | S2: =VLOOKUP($F2,Munition!$B:$P,10,FALSE) -> 16 | T2: =VLOOKUP($F2,Munition!$B:$P,11,FALSE) -> 265 | U2: =T2 * POWER(I2/S2,0.25) -> 265 | V2: =VLOOKUP($F2,Munition!$B:$P,5,FALSE) -> 9.3 | W2: =0.5 * (V2/1000) * (U2^2) -> 326.54625 | X2: =VLOOKUP($F2,Munition!$B:$P,15,FALSE) -> 203.93094 | Y2: =VLOOKUP($F2,Munition!$B:$P,9,FALSE) -> 1 | Z2: =VLOOKUP($F2,Munition!$B:$P,14,FALSE) -> 7.8210299e-06 | AA2: =0.0000001 * X2 * (2 * W2 / (V2/1000)) * Y2 -> 1.432105 | AB2: =0.0000001 * $X2 * (2 * $W2 * EXP(-(2*$Z2/($V2/1000)) * J2) / ($V2/1000)) * $Y2 -> 1.4225025 | AC2: =0.0000001 * $X2 * (2 * $W2 * EXP(-(2*$Z2/($V2/1000)) * K2) / ($V2/1000)) * $Y2 -> 1.4129644 | AD2: =0.0000001 * $X2 * (2 * $W2 * EXP(-(2*$Z2/($V2/1000)) * L2) / ($V2/1000)) * $Y2 -> 1.3754471 | AE2: =0.0000001 * $X2 * (2 * $W2 * EXP(-(2*$Z2/($V2/1000)) * M2) / ($V2/1000)) * $Y2 -> 1.3210306 | AF2: =IF(INT(SQRT(W2)/12)=0, MOD(INT(SQRT(W2)/4),3), INT(SQRT(W2)/12) & "D6" & IF(MOD(INT(SQRT(W2)/4),3)=0, "", "+" & MOD(INT(SQRT(W2)/4),3))) -> 1D6+1 | AG2: =IF((SQRT($W2)*(7/AA2))>=(SQRT($W2)),"-",IF(INT(SQRT($W2)*(7/AA2)/12)=0, MOD(INT(SQRT($W2)*(7/AA2)/4),3), INT(SQRT($W2)*(7/AA2)/12) & IF(MOD(INT(SQRT($W2)*(7/AA2)/4),3)=0, "", "+" & MOD(INT(SQRT($W2)*(7/AA2)/4),3)))) -> - | AH2: =IF((SQRT($W2)*(7/AB2))>=(SQRT($W2)),"-",IF(INT(SQRT($W2)*(7/AB2)/12)=0, MOD(INT(SQRT($W2)*(7/AB2)/4),3), INT(SQRT($W2)*(7/AB2)/12) & IF(MOD(INT(SQRT($W2)*(7/AB2)/4),3)=0, "", "+" & MOD(INT(SQRT($W2)*(7/AB2)/4),3)))) -> - | AI2: =IF((SQRT($W2)*(7/AC2))>=(SQRT($W2)),"-",IF(INT(SQRT($W2)*(7/AC2)/12)=0, MOD(INT(SQRT($W2)*(7/AC2)/4),3), INT(SQRT($W2)*(7/AC2)/12) & IF(MOD(INT(SQRT($W2)*(7/AC2)/4),3)=0, "", "+" & MOD(INT(SQRT($W2)*(7/AC2)/4),3)))) -> - | AJ2: =IF((SQRT($W2)*(7/AD2))>=(SQRT($W2)),"-",IF(INT(SQRT($W2)*(7/AD2)/12)=0, MOD(INT(SQRT($W2)*(7/AD2)/4),3), INT(SQRT($W2)*(7/AD2)/12) & IF(MOD(INT(SQRT($W2)*(7/AD2)/4),3)=0, "", "+" & MOD(INT(SQRT($W2)*(7/AD2)/4),3)))) -> - | AK2: 1965
A3: Armes à feu\Fusil Sniper | B3: Accuracy international - AW50F | C3: powder_projectiles | D3: powder_projectiles | F3: .50 BMG | G3: 12,7x99 | H3: 15 | I3: 27 | J3: 150 | K3: 300 | L3: 900 | M3: 1800 | N3: 2 | P3: 5 | Q3: BA | R3: 1 | S3: =VLOOKUP($F3,Munition!$B:$P,10,FALSE) -> 30 | T3: =VLOOKUP($F3,Munition!$B:$P,11,FALSE) -> 903 | U3: =T3 * POWER(I3/S3,0.25) -> 879.52538 | V3: =VLOOKUP($F3,Munition!$B:$P,5,FALSE) -> 42 | W3: =0.5 * (V3/1000) * (U3^2) -> 16244.863 | X3: =VLOOKUP($F3,Munition!$B:$P,15,FALSE) -> 331.55224 | Y3: =VLOOKUP($F3,Munition!$B:$P,9,FALSE) -> 1 | Z3: =VLOOKUP($F3,Munition!$B:$P,14,FALSE) -> 2.7156354e-05 | AA3: =0.0000001 * X3 * (2 * W3 / (V3/1000)) * Y3 -> 25.647718 | AB3: =0.0000001 * $X3 * (2 * $W3 * EXP(-(2*$Z3/($V3/1000)) * J3) / ($V3/1000)) * $Y3 -> 21.125495 | AC3: =0.0000001 * $X3 * (2 * $W3 * EXP(-(2*$Z3/($V3/1000)) * K3) / ($V3/1000)) * $Y3 -> 17.400634 | AD3: =0.0000001 * $X3 * (2 * $W3 * EXP(-(2*$Z3/($V3/1000)) * L3) / ($V3/1000)) * $Y3 -> 8.0093599 | AE3: =0.0000001 * $X3 * (2 * $W3 * EXP(-(2*$Z3/($V3/1000)) * M3) / ($V3/1000)) * $Y3 -> 2.5011912 | AF3: =IF(INT(SQRT(W3)/12)=0, MOD(INT(SQRT(W3)/4),3), INT(SQRT(W3)/12) & "D6" & IF(MOD(INT(SQRT(W3)/4),3)=0, "", "+" & MOD(INT(SQRT(W3)/4),3))) -> 10D6+1 | AG3: =IF((SQRT($W3)*(7/AA3))>=(SQRT($W3)),"-",IF(INT(SQRT($W3)*(7/AA3)/12)=0, MOD(INT(SQRT($W3)*(7/AA3)/4),3), INT(SQRT($W3)*(7/AA3)/12) & IF(MOD(INT(SQRT($W3)*(7/AA3)/4),3)=0, "", "+" & MOD(INT(SQRT($W3)*(7/AA3)/4),3)))) -> 2+2 | AH3: =IF((SQRT($W3)*(7/AB3))>=(SQRT($W3)),"-",IF(INT(SQRT($W3)*(7/AB3)/12)=0, MOD(INT(SQRT($W3)*(7/AB3)/4),3), INT(SQRT($W3)*(7/AB3)/12) & IF(MOD(INT(SQRT($W3)*(7/AB3)/4),3)=0, "", "+" & MOD(INT(SQRT($W3)*(7/AB3)/4),3)))) -> 3+1 | AI3: =IF((SQRT($W3)*(7/AC3))>=(SQRT($W3)),"-",IF(INT(SQRT($W3)*(7/AC3)/12)=0, MOD(INT(SQRT($W3)*(7/AC3)/4),3), INT(SQRT($W3)*(7/AC3)/12) & IF(MOD(INT(SQRT($W3)*(7/AC3)/4),3)=0, "", "+" & MOD(INT(SQRT($W3)*(7/AC3)/4),3)))) -> 4 | AJ3: =IF((SQRT($W3)*(7/AD3))>=(SQRT($W3)),"-",IF(INT(SQRT($W3)*(7/AD3)/12)=0, MOD(INT(SQRT($W3)*(7/AD3)/4),3), INT(SQRT($W3)*(7/AD3)/12) & IF(MOD(INT(SQRT($W3)*(7/AD3)/4),3)=0, "", "+" & MOD(INT(SQRT($W3)*(7/AD3)/4),3)))) -> 9 | AK3: 1998
A4: Armes à feu\Fusil | B4: Accuracy internationnal - AT308 | C4: powder_projectiles | D4: powder_projectiles | F4: .308 Winchester Sub | G4: 7,62x51 | H4: 6.3 | I4: 22 | J4: 50 | K4: 100 | L4: 300 | M4: 600 | N4: 1 | P4: 10 | Q4: BA | R4: 1 | S4: =VLOOKUP($F4,Munition!$B:$P,10,FALSE) -> 22 | T4: =VLOOKUP($F4,Munition!$B:$P,11,FALSE) -> 325 | U4: =T4 * POWER(I4/S4,0.25) -> 325 | V4: =VLOOKUP($F4,Munition!$B:$P,5,FALSE) -> 13 | W4: =0.5 * (V4/1000) * (U4^2) -> 686.5625 | X4: =VLOOKUP($F4,Munition!$B:$P,15,FALSE) -> 285.06476 | Y4: =VLOOKUP($F4,Munition!$B:$P,9,FALSE) -> 1 | Z4: =VLOOKUP($F4,Munition!$B:$P,14,FALSE) -> 6.9830624e-06 | AA4: =0.0000001 * X4 * (2 * W4 / (V4/1000)) * Y4 -> 3.0109965 | AB4: =0.0000001 * $X4 * (2 * $W4 * EXP(-(2*$Z4/($V4/1000)) * J4) / ($V4/1000)) * $Y4 -> 2.8535254 | AC4: =0.0000001 * $X4 * (2 * $W4 * EXP(-(2*$Z4/($V4/1000)) * K4) / ($V4/1000)) * $Y4 -> 2.7042899 | AD4: =0.0000001 * $X4 * (2 * $W4 * EXP(-(2*$Z4/($V4/1000)) * L4) / ($V4/1000)) * $Y4 -> 2.1814197 | AE4: =0.0000001 * $X4 * (2 * $W4 * EXP(-(2*$Z4/($V4/1000)) * M4) / ($V4/1000)) * $Y4 -> 1.5804043 | AF4: =IF(INT(SQRT(W4)/12)=0, MOD(INT(SQRT(W4)/4),3), INT(SQRT(W4)/12) & "D6" & IF(MOD(INT(SQRT(W4)/4),3)=0, "", "+" & MOD(INT(SQRT(W4)/4),3))) -> 2D6 | AG4: =IF((SQRT($W4)*(7/AA4))>=(SQRT($W4)),"-",IF(INT(SQRT($W4)*(7/AA4)/12)=0, MOD(INT(SQRT($W4)*(7/AA4)/4),3), INT(SQRT($W4)*(7/AA4)/12) & IF(MOD(INT(SQRT($W4)*(7/AA4)/4),3)=0, "", "+" & MOD(INT(SQRT($W4)*(7/AA4)/4),3)))) -> - | AH4: =IF((SQRT($W4)*(7/AB4))>=(SQRT($W4)),"-",IF(INT(SQRT($W4)*(7/AB4)/12)=0, MOD(INT(SQRT($W4)*(7/AB4)/4),3), INT(SQRT($W4)*(7/AB4)/12) & IF(MOD(INT(SQRT($W4)*(7/AB4)/4),3)=0, "", "+" & MOD(INT(SQRT($W4)*(7/AB4)/4),3)))) -> - | AI4: =IF((SQRT($W4)*(7/AC4))>=(SQRT($W4)),"-",IF(INT(SQRT($W4)*(7/AC4)/12)=0, MOD(INT(SQRT($W4)*(7/AC4)/4),3), INT(SQRT($W4)*(7/AC4)/12) & IF(MOD(INT(SQRT($W4)*(7/AC4)/4),3)=0, "", "+" & MOD(INT(SQRT($W4)*(7/AC4)/4),3)))) -> - | AJ4: =IF((SQRT($W4)*(7/AD4))>=(SQRT($W4)),"-",IF(INT(SQRT($W4)*(7/AD4)/12)=0, MOD(INT(SQRT($W4)*(7/AD4)/4),3), INT(SQRT($W4)*(7/AD4)/12) & IF(MOD(INT(SQRT($W4)*(7/AD4)/4),3)=0, "", "+" & MOD(INT(SQRT($W4)*(7/AD4)/4),3)))) -> - | AK4: 1982
A5: Armes à feu\Mitrailleuse | B5: ARES - LMG-1 | C5: powder_projectiles | D5: powder_projectiles | F5: 5,56 M193 | G5: 5,56x45 | H5: 5.7 | I5: 16 | J5: 100 | K5: 200 | L5: 600 | M5: 1200 | N5: 1 | O5: 5 | P5: 50 | Q5: 50 | R5: 10 | S5: =VLOOKUP($F5,Munition!$B:$P,10,FALSE) -> 20 | T5: =VLOOKUP($F5,Munition!$B:$P,11,FALSE) -> 878 | U5: =T5 * POWER(I5/S5,0.25) -> 830.36113 | V5: =VLOOKUP($F5,Munition!$B:$P,5,FALSE) -> 3.56 | W5: =0.5 * (V5/1000) * (U5^2) -> 1227.3093 | X5: =VLOOKUP($F5,Munition!$B:$P,15,FALSE) -> 146.62585 | Y5: =VLOOKUP($F5,Munition!$B:$P,9,FALSE) -> 1 | Z5: =VLOOKUP($F5,Munition!$B:$P,14,FALSE) -> 3.7177961e-06 | AA5: =0.0000001 * X5 * (2 * W5 / (V5/1000)) * Y5 -> 10.109846 | AB5: =0.0000001 * $X5 * (2 * $W5 * EXP(-(2*$Z5/($V5/1000)) * J5) / ($V5/1000)) * $Y5 -> 8.2041891 | AC5: =0.0000001 * $X5 * (2 * $W5 * EXP(-(2*$Z5/($V5/1000)) * K5) / ($V5/1000)) * $Y5 -> 6.6577391 | AD5: =0.0000001 * $X5 * (2 * $W5 * EXP(-(2*$Z5/($V5/1000)) * L5) / ($V5/1000)) * $Y5 -> 2.8872952 | AE5: =0.0000001 * $X5 * (2 * $W5 * EXP(-(2*$Z5/($V5/1000)) * M5) / ($V5/1000)) * $Y5 -> 0.82458954 | AF5: =IF(INT(SQRT(W5)/12)=0, MOD(INT(SQRT(W5)/4),3), INT(SQRT(W5)/12) & "D6" & IF(MOD(INT(SQRT(W5)/4),3)=0, "", "+" & MOD(INT(SQRT(W5)/4),3))) -> 2D6+2 | AG5: =IF((SQRT($W5)*(7/AA5))>=(SQRT($W5)),"-",IF(INT(SQRT($W5)*(7/AA5)/12)=0, MOD(INT(SQRT($W5)*(7/AA5)/4),3), INT(SQRT($W5)*(7/AA5)/12) & IF(MOD(INT(SQRT($W5)*(7/AA5)/4),3)=0, "", "+" & MOD(INT(SQRT($W5)*(7/AA5)/4),3)))) -> 2 | AH5: =IF((SQRT($W5)*(7/AB5))>=(SQRT($W5)),"-",IF(INT(SQRT($W5)*(7/AB5)/12)=0, MOD(INT(SQRT($W5)*(7/AB5)/4),3), INT(SQRT($W5)*(7/AB5)/12) & IF(MOD(INT(SQRT($W5)*(7/AB5)/4),3)=0, "", "+" & MOD(INT(SQRT($W5)*(7/AB5)/4),3)))) -> 2+1 | AI5: =IF((SQRT($W5)*(7/AC5))>=(SQRT($W5)),"-",IF(INT(SQRT($W5)*(7/AC5)/12)=0, MOD(INT(SQRT($W5)*(7/AC5)/4),3), INT(SQRT($W5)*(7/AC5)/12) & IF(MOD(INT(SQRT($W5)*(7/AC5)/4),3)=0, "", "+" & MOD(INT(SQRT($W5)*(7/AC5)/4),3)))) -> - | AJ5: =IF((SQRT($W5)*(7/AD5))>=(SQRT($W5)),"-",IF(INT(SQRT($W5)*(7/AD5)/12)=0, MOD(INT(SQRT($W5)*(7/AD5)/4),3), INT(SQRT($W5)*(7/AD5)/12) & IF(MOD(INT(SQRT($W5)*(7/AD5)/4),3)=0, "", "+" & MOD(INT(SQRT($W5)*(7/AD5)/4),3)))) -> - | AK5: 1986
A6: Armes à feu\Pistolet auto | B6: Ares Inc - FMG | C6: powder_projectiles | D6: powder_projectiles | F6: 9 P | G6: 9x19 | H6: 1.8 | I6: 5 | J6: 16 | K6: 32 | L6: 96 | M6: 192 | N6: 2 | O6: 10 | P6: 28 | Q6: 1/55 | R6: 10 | S6: =VLOOKUP($F6,Munition!$B:$P,10,FALSE) -> 4.5 | T6: =VLOOKUP($F6,Munition!$B:$P,11,FALSE) -> 450 | U6: =T6 * POWER(I6/S6,0.25) -> 462.01054 | V6: =VLOOKUP($F6,Munition!$B:$P,5,FALSE) -> 6.75 | W6: =0.5 * (V6/1000) * (U6^2) -> 720.40638 | X6: =VLOOKUP($F6,Munition!$B:$P,15,FALSE) -> 106.1033 | Y6: =VLOOKUP($F6,Munition!$B:$P,9,FALSE) -> 1 | Z6: =VLOOKUP($F6,Munition!$B:$P,14,FALSE) -> 1.5586227e-05 | AA6: =0.0000001 * X6 * (2 * W6 / (V6/1000)) * Y6 -> 2.2648145 | AB6: =0.0000001 * $X6 * (2 * $W6 * EXP(-(2*$Z6/($V6/1000)) * J6) / ($V6/1000)) * $Y6 -> 2.1035 | AC6: =0.0000001 * $X6 * (2 * $W6 * EXP(-(2*$Z6/($V6/1000)) * K6) / ($V6/1000)) * $Y6 -> 1.9536753 | AD6: =0.0000001 * $X6 * (2 * $W6 * EXP(-(2*$Z6/($V6/1000)) * L6) / ($V6/1000)) * $Y6 -> 1.4537571 | AE6: =0.0000001 * $X6 * (2 * $W6 * EXP(-(2*$Z6/($V6/1000)) * M6) / ($V6/1000)) * $Y6 -> 0.93314915 | AF6: =IF(INT(SQRT(W6)/12)=0, MOD(INT(SQRT(W6)/4),3), INT(SQRT(W6)/12) & "D6" & IF(MOD(INT(SQRT(W6)/4),3)=0, "", "+" & MOD(INT(SQRT(W6)/4),3))) -> 2D6 | AG6: =IF((SQRT($W6)*(7/AA6))>=(SQRT($W6)),"-",IF(INT(SQRT($W6)*(7/AA6)/12)=0, MOD(INT(SQRT($W6)*(7/AA6)/4),3), INT(SQRT($W6)*(7/AA6)/12) & IF(MOD(INT(SQRT($W6)*(7/AA6)/4),3)=0, "", "+" & MOD(INT(SQRT($W6)*(7/AA6)/4),3)))) -> - | AH6: =IF((SQRT($W6)*(7/AB6))>=(SQRT($W6)),"-",IF(INT(SQRT($W6)*(7/AB6)/12)=0, MOD(INT(SQRT($W6)*(7/AB6)/4),3), INT(SQRT($W6)*(7/AB6)/12) & IF(MOD(INT(SQRT($W6)*(7/AB6)/4),3)=0, "", "+" & MOD(INT(SQRT($W6)*(7/AB6)/4),3)))) -> - | AI6: =IF((SQRT($W6)*(7/AC6))>=(SQRT($W6)),"-",IF(INT(SQRT($W6)*(7/AC6)/12)=0, MOD(INT(SQRT($W6)*(7/AC6)/4),3), INT(SQRT($W6)*(7/AC6)/12) & IF(MOD(INT(SQRT($W6)*(7/AC6)/4),3)=0, "", "+" & MOD(INT(SQRT($W6)*(7/AC6)/4),3)))) -> - | AJ6: =IF((SQRT($W6)*(7/AD6))>=(SQRT($W6)),"-",IF(INT(SQRT($W6)*(7/AD6)/12)=0, MOD(INT(SQRT($W6)*(7/AD6)/4),3), INT(SQRT($W6)*(7/AD6)/12) & IF(MOD(INT(SQRT($W6)*(7/AD6)/4),3)=0, "", "+" & MOD(INT(SQRT($W6)*(7/AD6)/4),3)))) -> - | AK6: 1983
A7: Armes à feu\Fusil d'assaut | B7: Armalite - AR 18 | C7: powder_projectiles | D7: powder_projectiles | F7: 5,56 M193 | G7: 5,56x45 | H7: 3.9 | I7: 18 | J7: 50 | K7: 100 | L7: 300 | M7: 600 | N7: 2 | O7: 10 | P7: 30 | Q7: 1/65 | R7: 10 | S7: =VLOOKUP($F7,Munition!$B:$P,10,FALSE) -> 20 | T7: =VLOOKUP($F7,Munition!$B:$P,11,FALSE) -> 878 | U7: =T7 * POWER(I7/S7,0.25) -> 855.17529 | V7: =VLOOKUP($F7,Munition!$B:$P,5,FALSE) -> 3.56 | W7: =0.5 * (V7/1000) * (U7^2) -> 1301.7581 | X7: =VLOOKUP($F7,Munition!$B:$P,15,FALSE) -> 146.62585 | Y7: =VLOOKUP($F7,Munition!$B:$P,9,FALSE) -> 1 | Z7: =VLOOKUP($F7,Munition!$B:$P,14,FALSE) -> 3.7177961e-06 | AA7: =0.0000001 * X7 * (2 * W7 / (V7/1000)) * Y7 -> 10.723111 | AB7: =0.0000001 * $X7 * (2 * $W7 * EXP(-(2*$Z7/($V7/1000)) * J7) / ($V7/1000)) * $Y7 -> 9.6597608 | AC7: =0.0000001 * $X7 * (2 * $W7 * EXP(-(2*$Z7/($V7/1000)) * K7) / ($V7/1000)) * $Y7 -> 8.7018567 | AD7: =0.0000001 * $X7 * (2 * $W7 * EXP(-(2*$Z7/($V7/1000)) * L7) / ($V7/1000)) * $Y7 -> 5.7305214 | AE7: =0.0000001 * $X7 * (2 * $W7 * EXP(-(2*$Z7/($V7/1000)) * M7) / ($V7/1000)) * $Y7 -> 3.062439 | AF7: =IF(INT(SQRT(W7)/12)=0, MOD(INT(SQRT(W7)/4),3), INT(SQRT(W7)/12) & "D6" & IF(MOD(INT(SQRT(W7)/4),3)=0, "", "+" & MOD(INT(SQRT(W7)/4),3))) -> 3D6 | AG7: =IF((SQRT($W7)*(7/AA7))>=(SQRT($W7)),"-",IF(INT(SQRT($W7)*(7/AA7)/12)=0, MOD(INT(SQRT($W7)*(7/AA7)/4),3), INT(SQRT($W7)*(7/AA7)/12) & IF(MOD(INT(SQRT($W7)*(7/AA7)/4),3)=0, "", "+" & MOD(INT(SQRT($W7)*(7/AA7)/4),3)))) -> 1+2 | AH7: =IF((SQRT($W7)*(7/AB7))>=(SQRT($W7)),"-",IF(INT(SQRT($W7)*(7/AB7)/12)=0, MOD(INT(SQRT($W7)*(7/AB7)/4),3), INT(SQRT($W7)*(7/AB7)/12) & IF(MOD(INT(SQRT($W7)*(7/AB7)/4),3)=0, "", "+" & MOD(INT(SQRT($W7)*(7/AB7)/4),3)))) -> 2 | AI7: =IF((SQRT($W7)*(7/AC7))>=(SQRT($W7)),"-",IF(INT(SQRT($W7)*(7/AC7)/12)=0, MOD(INT(SQRT($W7)*(7/AC7)/4),3), INT(SQRT($W7)*(7/AC7)/12) & IF(MOD(INT(SQRT($W7)*(7/AC7)/4),3)=0, "", "+" & MOD(INT(SQRT($W7)*(7/AC7)/4),3)))) -> 2+1 | AJ7: =IF((SQRT($W7)*(7/AD7))>=(SQRT($W7)),"-",IF(INT(SQRT($W7)*(7/AD7)/12)=0, MOD(INT(SQRT($W7)*(7/AD7)/4),3), INT(SQRT($W7)*(7/AD7)/12) & IF(MOD(INT(SQRT($W7)*(7/AD7)/4),3)=0, "", "+" & MOD(INT(SQRT($W7)*(7/AD7)/4),3)))) -> - | AK7: 1963
A8: Armes à feu\Fusil d'assaut | B8: Armurier Breton - FSA Commando | C8: powder_projectiles | D8: powder_projectiles | F8: 7,62 N | G8: 7,62x51 | H8: 3.96 | I8: 11 | J8: 50 | K8: 100 | L8: 300 | M8: 600 | N8: 2 | O8: 3 | P8: 20 | Q8: 1/3 | R8: 3 | S8: =VLOOKUP($F8,Munition!$B:$P,10,FALSE) -> 22 | T8: =VLOOKUP($F8,Munition!$B:$P,11,FALSE) -> 832 | U8: =T8 * POWER(I8/S8,0.25) -> 699.62582 | V8: =VLOOKUP($F8,Munition!$B:$P,5,FALSE) -> 9.45 | W8: =0.5 * (V8/1000) * (U8^2) -> 2312.7754 | X8: =VLOOKUP($F8,Munition!$B:$P,15,FALSE) -> 207.22015 | Y8: =VLOOKUP($F8,Munition!$B:$P,9,FALSE) -> 1 | Z8: =VLOOKUP($F8,Munition!$B:$P,14,FALSE) -> 6.9830624e-06 | AA8: =0.0000001 * X8 * (2 * W8 / (V8/1000)) * Y8 -> 10.142935 | AB8: =0.0000001 * $X8 * (2 * $W8 * EXP(-(2*$Z8/($V8/1000)) * J8) / ($V8/1000)) * $Y8 -> 9.4204472 | AC8: =0.0000001 * $X8 * (2 * $W8 * EXP(-(2*$Z8/($V8/1000)) * K8) / ($V8/1000)) * $Y8 -> 8.7494227 | AD8: =0.0000001 * $X8 * (2 * $W8 * EXP(-(2*$Z8/($V8/1000)) * L8) / ($V8/1000)) * $Y8 -> 6.5104485 | AE8: =0.0000001 * $X8 * (2 * $W8 * EXP(-(2*$Z8/($V8/1000)) * M8) / ($V8/1000)) * $Y8 -> 4.1788635 | AF8: =IF(INT(SQRT(W8)/12)=0, MOD(INT(SQRT(W8)/4),3), INT(SQRT(W8)/12) & "D6" & IF(MOD(INT(SQRT(W8)/4),3)=0, "", "+" & MOD(INT(SQRT(W8)/4),3))) -> 4D6 | AG8: =IF((SQRT($W8)*(7/AA8))>=(SQRT($W8)),"-",IF(INT(SQRT($W8)*(7/AA8)/12)=0, MOD(INT(SQRT($W8)*(7/AA8)/4),3), INT(SQRT($W8)*(7/AA8)/12) & IF(MOD(INT(SQRT($W8)*(7/AA8)/4),3)=0, "", "+" & MOD(INT(SQRT($W8)*(7/AA8)/4),3)))) -> 2+2 | AH8: =IF((SQRT($W8)*(7/AB8))>=(SQRT($W8)),"-",IF(INT(SQRT($W8)*(7/AB8)/12)=0, MOD(INT(SQRT($W8)*(7/AB8)/4),3), INT(SQRT($W8)*(7/AB8)/12) & IF(MOD(INT(SQRT($W8)*(7/AB8)/4),3)=0, "", "+" & MOD(INT(SQRT($W8)*(7/AB8)/4),3)))) -> 2+2 | AI8: =IF((SQRT($W8)*(7/AC8))>=(SQRT($W8)),"-",IF(INT(SQRT($W8)*(7/AC8)/12)=0, MOD(INT(SQRT($W8)*(7/AC8)/4),3), INT(SQRT($W8)*(7/AC8)/12) & IF(MOD(INT(SQRT($W8)*(7/AC8)/4),3)=0, "", "+" & MOD(INT(SQRT($W8)*(7/AC8)/4),3)))) -> 3 | AJ8: =IF((SQRT($W8)*(7/AD8))>=(SQRT($W8)),"-",IF(INT(SQRT($W8)*(7/AD8)/12)=0, MOD(INT(SQRT($W8)*(7/AD8)/4),3), INT(SQRT($W8)*(7/AD8)/12) & IF(MOD(INT(SQRT($W8)*(7/AD8)/4),3)=0, "", "+" & MOD(INT(SQRT($W8)*(7/AD8)/4),3)))) -> - | AK8: 2003
A9: Armes à feu\Fusil Sniper | B9: Armurier Breton - FSA Précision | C9: powder_projectiles | D9: powder_projectiles | F9: 7,62 N | G9: 7,62x51 | H9: 3.96 | I9: 22 | J9: 133 | K9: 266 | L9: 798 | M9: 1596 | N9: 2 | O9: 3 | P9: 20 | Q9: 1/3 | R9: 3 | S9: =VLOOKUP($F9,Munition!$B:$P,10,FALSE) -> 22 | T9: =VLOOKUP($F9,Munition!$B:$P,11,FALSE) -> 832 | U9: =T9 * POWER(I9/S9,0.25) -> 832 | V9: =VLOOKUP($F9,Munition!$B:$P,5,FALSE) -> 9.45 | W9: =0.5 * (V9/1000) * (U9^2) -> 3270.7584 | X9: =VLOOKUP($F9,Munition!$B:$P,15,FALSE) -> 207.22015 | Y9: =VLOOKUP($F9,Munition!$B:$P,9,FALSE) -> 1 | Z9: =VLOOKUP($F9,Munition!$B:$P,14,FALSE) -> 6.9830624e-06 | AA9: =0.0000001 * X9 * (2 * W9 / (V9/1000)) * Y9 -> 14.344276 | AB9: =0.0000001 * $X9 * (2 * $W9 * EXP(-(2*$Z9/($V9/1000)) * J9) / ($V9/1000)) * $Y9 -> 11.784566 | AC9: =0.0000001 * $X9 * (2 * $W9 * EXP(-(2*$Z9/($V9/1000)) * K9) / ($V9/1000)) * $Y9 -> 9.6816315 | AD9: =0.0000001 * $X9 * (2 * $W9 * EXP(-(2*$Z9/($V9/1000)) * L9) / ($V9/1000)) * $Y9 -> 4.4105056 | AE9: =0.0000001 * $X9 * (2 * $W9 * EXP(-(2*$Z9/($V9/1000)) * M9) / ($V9/1000)) * $Y9 -> 1.35612 | AF9: =IF(INT(SQRT(W9)/12)=0, MOD(INT(SQRT(W9)/4),3), INT(SQRT(W9)/12) & "D6" & IF(MOD(INT(SQRT(W9)/4),3)=0, "", "+" & MOD(INT(SQRT(W9)/4),3))) -> 4D6+2 | AG9: =IF((SQRT($W9)*(7/AA9))>=(SQRT($W9)),"-",IF(INT(SQRT($W9)*(7/AA9)/12)=0, MOD(INT(SQRT($W9)*(7/AA9)/4),3), INT(SQRT($W9)*(7/AA9)/12) & IF(MOD(INT(SQRT($W9)*(7/AA9)/4),3)=0, "", "+" & MOD(INT(SQRT($W9)*(7/AA9)/4),3)))) -> 2 | AH9: =IF((SQRT($W9)*(7/AB9))>=(SQRT($W9)),"-",IF(INT(SQRT($W9)*(7/AB9)/12)=0, MOD(INT(SQRT($W9)*(7/AB9)/4),3), INT(SQRT($W9)*(7/AB9)/12) & IF(MOD(INT(SQRT($W9)*(7/AB9)/4),3)=0, "", "+" & MOD(INT(SQRT($W9)*(7/AB9)/4),3)))) -> 2+2 | AI9: =IF((SQRT($W9)*(7/AC9))>=(SQRT($W9)),"-",IF(INT(SQRT($W9)*(7/AC9)/12)=0, MOD(INT(SQRT($W9)*(7/AC9)/4),3), INT(SQRT($W9)*(7/AC9)/12) & IF(MOD(INT(SQRT($W9)*(7/AC9)/4),3)=0, "", "+" & MOD(INT(SQRT($W9)*(7/AC9)/4),3)))) -> 3+1 | AJ9: =IF((SQRT($W9)*(7/AD9))>=(SQRT($W9)),"-",IF(INT(SQRT($W9)*(7/AD9)/12)=0, MOD(INT(SQRT($W9)*(7/AD9)/4),3), INT(SQRT($W9)*(7/AD9)/12) & IF(MOD(INT(SQRT($W9)*(7/AD9)/4),3)=0, "", "+" & MOD(INT(SQRT($W9)*(7/AD9)/4),3)))) -> - | AK9: 2003
A10: Armes à feu\Fusil Sniper | B10: Armurier Breton - FSA Précision S | C10: powder_projectiles | D10: powder_projectiles | F10: 7,62 N | G10: 7,62x51 | H10: 4.1 | I10: 20 | J10: 83 | K10: 166 | L10: 498 | M10: 996 | N10: 2 | O10: 3 | P10: 20 | Q10: 1/3 | R10: 3 | S10: =VLOOKUP($F10,Munition!$B:$P,10,FALSE) -> 22 | T10: =VLOOKUP($F10,Munition!$B:$P,11,FALSE) -> 832 | U10: =T10 * POWER(I10/S10,0.25) -> 812.4098 | V10: =VLOOKUP($F10,Munition!$B:$P,5,FALSE) -> 9.45 | W10: =0.5 * (V10/1000) * (U10^2) -> 3118.5458 | X10: =VLOOKUP($F10,Munition!$B:$P,15,FALSE) -> 207.22015 | Y10: =VLOOKUP($F10,Munition!$B:$P,9,FALSE) -> 1 | Z10: =VLOOKUP($F10,Munition!$B:$P,14,FALSE) -> 6.9830624e-06 | AA10: =0.0000001 * X10 * (2 * W10 / (V10/1000)) * Y10 -> 13.676731 | AB10: =0.0000001 * $X10 * (2 * $W10 * EXP(-(2*$Z10/($V10/1000)) * J10) / ($V10/1000)) * $Y10 -> 12.097883 | AC10: =0.0000001 * $X10 * (2 * $W10 * EXP(-(2*$Z10/($V10/1000)) * K10) / ($V10/1000)) * $Y10 -> 10.701298 | AD10: =0.0000001 * $X10 * (2 * $W10 * EXP(-(2*$Z10/($V10/1000)) * L10) / ($V10/1000)) * $Y10 -> 6.5515606 | AE10: =0.0000001 * $X10 * (2 * $W10 * EXP(-(2*$Z10/($V10/1000)) * M10) / ($V10/1000)) * $Y10 -> 3.1383923 | AF10: =IF(INT(SQRT(W10)/12)=0, MOD(INT(SQRT(W10)/4),3), INT(SQRT(W10)/12) & "D6" & IF(MOD(INT(SQRT(W10)/4),3)=0, "", "+" & MOD(INT(SQRT(W10)/4),3))) -> 4D6+1 | AG10: =IF((SQRT($W10)*(7/AA10))>=(SQRT($W10)),"-",IF(INT(SQRT($W10)*(7/AA10)/12)=0, MOD(INT(SQRT($W10)*(7/AA10)/4),3), INT(SQRT($W10)*(7/AA10)/12) & IF(MOD(INT(SQRT($W10)*(7/AA10)/4),3)=0, "", "+" & MOD(INT(SQRT($W10)*(7/AA10)/4),3)))) -> 2+1 | AH10: =IF((SQRT($W10)*(7/AB10))>=(SQRT($W10)),"-",IF(INT(SQRT($W10)*(7/AB10)/12)=0, MOD(INT(SQRT($W10)*(7/AB10)/4),3), INT(SQRT($W10)*(7/AB10)/12) & IF(MOD(INT(SQRT($W10)*(7/AB10)/4),3)=0, "", "+" & MOD(INT(SQRT($W10)*(7/AB10)/4),3)))) -> 2+2 | AI10: =IF((SQRT($W10)*(7/AC10))>=(SQRT($W10)),"-",IF(INT(SQRT($W10)*(7/AC10)/12)=0, MOD(INT(SQRT($W10)*(7/AC10)/4),3), INT(SQRT($W10)*(7/AC10)/12) & IF(MOD(INT(SQRT($W10)*(7/AC10)/4),3)=0, "", "+" & MOD(INT(SQRT($W10)*(7/AC10)/4),3)))) -> 3 | AJ10: =IF((SQRT($W10)*(7/AD10))>=(SQRT($W10)),"-",IF(INT(SQRT($W10)*(7/AD10)/12)=0, MOD(INT(SQRT($W10)*(7/AD10)/4),3), INT(SQRT($W10)*(7/AD10)/12) & IF(MOD(INT(SQRT($W10)*(7/AD10)/4),3)=0, "", "+" & MOD(INT(SQRT($W10)*(7/AD10)/4),3)))) -> - | AK10: 2003
A11: Armes à feu\Fusil pompe | B11: Atchisson - AA-12 | C11: powder_projectiles | D11: powder_projectiles | E11: AA-12 | F11: Cal. 12 G | G11: 18,5x70 | H11: 5.2 | I11: 18.5 | J11: 6 | K11: 12 | L11: 36 | M11: 72 | N11: 1 | O11: 3 | P11: 32 | Q11: 1/7 | R11: 2 | S11: =VLOOKUP($F11,Munition!$B:$P,10,FALSE) -> 20 | T11: =VLOOKUP($F11,Munition!$B:$P,11,FALSE) -> 408 | U11: =T11 * POWER(I11/S11,0.25) -> 400.12492 | V11: =VLOOKUP($F11,Munition!$B:$P,5,FALSE) -> 38 | W11: =0.5 * (V11/1000) * (U11^2) -> 3041.899 | X11: =VLOOKUP($F11,Munition!$B:$P,15,FALSE) -> 141.36772 | Y11: =VLOOKUP($F11,Munition!$B:$P,9,FALSE) -> 1 | Z11: =VLOOKUP($F11,Munition!$B:$P,14,FALSE) -> 9.8784927e-05 | AA11: =0.0000001 * X11 * (2 * W11 / (V11/1000)) * Y11 -> 2.2632965 | AB11: =0.0000001 * $X11 * (2 * $W11 * EXP(-(2*$Z11/($V11/1000)) * J11) / ($V11/1000)) * $Y11 -> 2.1937823 | AC11: =0.0000001 * $X11 * (2 * $W11 * EXP(-(2*$Z11/($V11/1000)) * K11) / ($V11/1000)) * $Y11 -> 2.1264032 | AD11: =0.0000001 * $X11 * (2 * $W11 * EXP(-(2*$Z11/($V11/1000)) * L11) / ($V11/1000)) * $Y11 -> 1.8769553 | AE11: =0.0000001 * $X11 * (2 * $W11 * EXP(-(2*$Z11/($V11/1000)) * M11) / ($V11/1000)) * $Y11 -> 1.5565619 | AF11: =IF(INT(SQRT(W11)/12)=0, MOD(INT(SQRT(W11)/4),3), INT(SQRT(W11)/12) & "D6" & IF(MOD(INT(SQRT(W11)/4),3)=0, "", "+" & MOD(INT(SQRT(W11)/4),3))) -> 4D6+1 | AG11: =IF((SQRT($W11)*(7/AA11))>=(SQRT($W11)),"-",IF(INT(SQRT($W11)*(7/AA11)/12)=0, MOD(INT(SQRT($W11)*(7/AA11)/4),3), INT(SQRT($W11)*(7/AA11)/12) & IF(MOD(INT(SQRT($W11)*(7/AA11)/4),3)=0, "", "+" & MOD(INT(SQRT($W11)*(7/AA11)/4),3)))) -> - | AH11: =IF((SQRT($W11)*(7/AB11))>=(SQRT($W11)),"-",IF(INT(SQRT($W11)*(7/AB11)/12)=0, MOD(INT(SQRT($W11)*(7/AB11)/4),3), INT(SQRT($W11)*(7/AB11)/12) & IF(MOD(INT(SQRT($W11)*(7/AB11)/4),3)=0, "", "+" & MOD(INT(SQRT($W11)*(7/AB11)/4),3)))) -> - | AI11: =IF((SQRT($W11)*(7/AC11))>=(SQRT($W11)),"-",IF(INT(SQRT($W11)*(7/AC11)/12)=0, MOD(INT(SQRT($W11)*(7/AC11)/4),3), INT(SQRT($W11)*(7/AC11)/12) & IF(MOD(INT(SQRT($W11)*(7/AC11)/4),3)=0, "", "+" & MOD(INT(SQRT($W11)*(7/AC11)/4),3)))) -> - | AJ11: =IF((SQRT($W11)*(7/AD11))>=(SQRT($W11)),"-",IF(INT(SQRT($W11)*(7/AD11)/12)=0, MOD(INT(SQRT($W11)*(7/AD11)/4),3), INT(SQRT($W11)*(7/AD11)/12) & IF(MOD(INT(SQRT($W11)*(7/AD11)/4),3)=0, "", "+" & MOD(INT(SQRT($W11)*(7/AD11)/4),3)))) -> - | AK11: 2005
A12: Armes à feu\Pistolet auto | B12: Auto mag corporation - .44 Automag | C12: powder_projectiles | D12: powder_projectiles | F12: .44 AMP | G12: 10,74x33 | H12: 1.8 | I12: 6.5 | J12: 8 | K12: 16 | L12: 48 | M12: 96 | N12: 3 | P12: 7 | Q12: SA | R12: 1 | S12: =VLOOKUP($F12,Munition!$B:$P,10,FALSE) -> 6 | T12: =VLOOKUP($F12,Munition!$B:$P,11,FALSE) -> 500 | U12: =T12 * POWER(I12/S12,0.25) -> 510.10612 | V12: =VLOOKUP($F12,Munition!$B:$P,5,FALSE) -> 19 | W12: =0.5 * (V12/1000) * (U12^2) -> 2471.9784 | X12: =VLOOKUP($F12,Munition!$B:$P,15,FALSE) -> 209.72739 | Y12: =VLOOKUP($F12,Munition!$B:$P,9,FALSE) -> 1 | Z12: =VLOOKUP($F12,Munition!$B:$P,14,FALSE) -> 2.2195479e-05 | AA12: =0.0000001 * X12 * (2 * W12 / (V12/1000)) * Y12 -> 5.4572798 | AB12: =0.0000001 * $X12 * (2 * $W12 * EXP(-(2*$Z12/($V12/1000)) * J12) / ($V12/1000)) * $Y12 -> 5.3562255 | AC12: =0.0000001 * $X12 * (2 * $W12 * EXP(-(2*$Z12/($V12/1000)) * K12) / ($V12/1000)) * $Y12 -> 5.2570424 | AD12: =0.0000001 * $X12 * (2 * $W12 * EXP(-(2*$Z12/($V12/1000)) * L12) / ($V12/1000)) * $Y12 -> 4.8783394 | AE12: =0.0000001 * $X12 * (2 * $W12 * EXP(-(2*$Z12/($V12/1000)) * M12) / ($V12/1000)) * $Y12 -> 4.3608164 | AF12: =IF(INT(SQRT(W12)/12)=0, MOD(INT(SQRT(W12)/4),3), INT(SQRT(W12)/12) & "D6" & IF(MOD(INT(SQRT(W12)/4),3)=0, "", "+" & MOD(INT(SQRT(W12)/4),3))) -> 4D6 | AG12: =IF((SQRT($W12)*(7/AA12))>=(SQRT($W12)),"-",IF(INT(SQRT($W12)*(7/AA12)/12)=0, MOD(INT(SQRT($W12)*(7/AA12)/4),3), INT(SQRT($W12)*(7/AA12)/12) & IF(MOD(INT(SQRT($W12)*(7/AA12)/4),3)=0, "", "+" & MOD(INT(SQRT($W12)*(7/AA12)/4),3)))) -> - | AH12: =IF((SQRT($W12)*(7/AB12))>=(SQRT($W12)),"-",IF(INT(SQRT($W12)*(7/AB12)/12)=0, MOD(INT(SQRT($W12)*(7/AB12)/4),3), INT(SQRT($W12)*(7/AB12)/12) & IF(MOD(INT(SQRT($W12)*(7/AB12)/4),3)=0, "", "+" & MOD(INT(SQRT($W12)*(7/AB12)/4),3)))) -> - | AI12: =IF((SQRT($W12)*(7/AC12))>=(SQRT($W12)),"-",IF(INT(SQRT($W12)*(7/AC12)/12)=0, MOD(INT(SQRT($W12)*(7/AC12)/4),3), INT(SQRT($W12)*(7/AC12)/12) & IF(MOD(INT(SQRT($W12)*(7/AC12)/4),3)=0, "", "+" & MOD(INT(SQRT($W12)*(7/AC12)/4),3)))) -> - | AJ12: =IF((SQRT($W12)*(7/AD12))>=(SQRT($W12)),"-",IF(INT(SQRT($W12)*(7/AD12)/12)=0, MOD(INT(SQRT($W12)*(7/AD12)/4),3), INT(SQRT($W12)*(7/AD12)/12) & IF(MOD(INT(SQRT($W12)*(7/AD12)/4),3)=0, "", "+" & MOD(INT(SQRT($W12)*(7/AD12)/4),3)))) -> - | AK12: 1971
A13: Armes à feu\Pistolet Mitrailleur | B13: Auto-Ordonnance Cie - Thompson Mle 1928 | C13: powder_projectiles | D13: powder_projectiles | F13: .45 ACP | G13: 11,43x23 | H13: 4.9 | I13: 10.5 | J13: 8 | K13: 16 | L13: 48 | M13: 96 | N13: 1 | O13: 5 | P13: 50 | Q13: 62 | R13: 10 | S13: =VLOOKUP($F13,Munition!$B:$P,10,FALSE) -> 5 | T13: =VLOOKUP($F13,Munition!$B:$P,11,FALSE) -> 285 | U13: =T13 * POWER(I13/S13,0.25) -> 343.08338 | V13: =VLOOKUP($F13,Munition!$B:$P,5,FALSE) -> 14.84 | W13: =0.5 * (V13/1000) * (U13^2) -> 873.38006 | X13: =VLOOKUP($F13,Munition!$B:$P,15,FALSE) -> 144.62773 | Y13: =VLOOKUP($F13,Munition!$B:$P,9,FALSE) -> 1 | Z13: =VLOOKUP($F13,Munition!$B:$P,14,FALSE) -> 2.8281403e-05 | AA13: =0.0000001 * X13 * (2 * W13 / (V13/1000)) * Y13 -> 1.7023581 | AB13: =0.0000001 * $X13 * (2 * $W13 * EXP(-(2*$Z13/($V13/1000)) * J13) / ($V13/1000)) * $Y13 -> 1.6512331 | AC13: =0.0000001 * $X13 * (2 * $W13 * EXP(-(2*$Z13/($V13/1000)) * K13) / ($V13/1000)) * $Y13 -> 1.6016435 | AD13: =0.0000001 * $X13 * (2 * $W13 * EXP(-(2*$Z13/($V13/1000)) * L13) / ($V13/1000)) * $Y13 -> 1.417737 | AE13: =0.0000001 * $X13 * (2 * $W13 * EXP(-(2*$Z13/($V13/1000)) * M13) / ($V13/1000)) * $Y13 -> 1.1807024 | AF13: =IF(INT(SQRT(W13)/12)=0, MOD(INT(SQRT(W13)/4),3), INT(SQRT(W13)/12) & "D6" & IF(MOD(INT(SQRT(W13)/4),3)=0, "", "+" & MOD(INT(SQRT(W13)/4),3))) -> 2D6+1 | AG13: =IF((SQRT($W13)*(7/AA13))>=(SQRT($W13)),"-",IF(INT(SQRT($W13)*(7/AA13)/12)=0, MOD(INT(SQRT($W13)*(7/AA13)/4),3), INT(SQRT($W13)*(7/AA13)/12) & IF(MOD(INT(SQRT($W13)*(7/AA13)/4),3)=0, "", "+" & MOD(INT(SQRT($W13)*(7/AA13)/4),3)))) -> - | AH13: =IF((SQRT($W13)*(7/AB13))>=(SQRT($W13)),"-",IF(INT(SQRT($W13)*(7/AB13)/12)=0, MOD(INT(SQRT($W13)*(7/AB13)/4),3), INT(SQRT($W13)*(7/AB13)/12) & IF(MOD(INT(SQRT($W13)*(7/AB13)/4),3)=0, "", "+" & MOD(INT(SQRT($W13)*(7/AB13)/4),3)))) -> - | AI13: =IF((SQRT($W13)*(7/AC13))>=(SQRT($W13)),"-",IF(INT(SQRT($W13)*(7/AC13)/12)=0, MOD(INT(SQRT($W13)*(7/AC13)/4),3), INT(SQRT($W13)*(7/AC13)/12) & IF(MOD(INT(SQRT($W13)*(7/AC13)/4),3)=0, "", "+" & MOD(INT(SQRT($W13)*(7/AC13)/4),3)))) -> - | AJ13: =IF((SQRT($W13)*(7/AD13))>=(SQRT($W13)),"-",IF(INT(SQRT($W13)*(7/AD13)/12)=0, MOD(INT(SQRT($W13)*(7/AD13)/4),3), INT(SQRT($W13)*(7/AD13)/12) & IF(MOD(INT(SQRT($W13)*(7/AD13)/4),3)=0, "", "+" & MOD(INT(SQRT($W13)*(7/AD13)/4),3)))) -> - | AK13: 1928
A14: Armes à feu\Fusil Sniper | B14: Barrett - M82A1 Light-Fifty | C14: powder_projectiles | D14: powder_projectiles | F14: .50 BMG | G14: 12,7x99 | H14: 14.1 | I14: 29 | J14: 150 | K14: 300 | L14: 900 | M14: 1800 | N14: 2 | P14: 10 | Q14: SA | R14: 1 | S14: =VLOOKUP($F14,Munition!$B:$P,10,FALSE) -> 30 | T14: =VLOOKUP($F14,Munition!$B:$P,11,FALSE) -> 903 | U14: =T14 * POWER(I14/S14,0.25) -> 895.37907 | V14: =VLOOKUP($F14,Munition!$B:$P,5,FALSE) -> 42 | W14: =0.5 * (V14/1000) * (U14^2) -> 16835.777 | X14: =VLOOKUP($F14,Munition!$B:$P,15,FALSE) -> 331.55224 | Y14: =VLOOKUP($F14,Munition!$B:$P,9,FALSE) -> 1 | Z14: =VLOOKUP($F14,Munition!$B:$P,14,FALSE) -> 2.7156354e-05 | AA14: =0.0000001 * X14 * (2 * W14 / (V14/1000)) * Y14 -> 26.580665 | AB14: =0.0000001 * $X14 * (2 * $W14 * EXP(-(2*$Z14/($V14/1000)) * J14) / ($V14/1000)) * $Y14 -> 21.893945 | AC14: =0.0000001 * $X14 * (2 * $W14 * EXP(-(2*$Z14/($V14/1000)) * K14) / ($V14/1000)) * $Y14 -> 18.03359 | AD14: =0.0000001 * $X14 * (2 * $W14 * EXP(-(2*$Z14/($V14/1000)) * L14) / ($V14/1000)) * $Y14 -> 8.300704 | AE14: =0.0000001 * $X14 * (2 * $W14 * EXP(-(2*$Z14/($V14/1000)) * M14) / ($V14/1000)) * $Y14 -> 2.5921732 | AF14: =IF(INT(SQRT(W14)/12)=0, MOD(INT(SQRT(W14)/4),3), INT(SQRT(W14)/12) & "D6" & IF(MOD(INT(SQRT(W14)/4),3)=0, "", "+" & MOD(INT(SQRT(W14)/4),3))) -> 10D6+2 | AG14: =IF((SQRT($W14)*(7/AA14))>=(SQRT($W14)),"-",IF(INT(SQRT($W14)*(7/AA14)/12)=0, MOD(INT(SQRT($W14)*(7/AA14)/4),3), INT(SQRT($W14)*(7/AA14)/12) & IF(MOD(INT(SQRT($W14)*(7/AA14)/4),3)=0, "", "+" & MOD(INT(SQRT($W14)*(7/AA14)/4),3)))) -> 2+2 | AH14: =IF((SQRT($W14)*(7/AB14))>=(SQRT($W14)),"-",IF(INT(SQRT($W14)*(7/AB14)/12)=0, MOD(INT(SQRT($W14)*(7/AB14)/4),3), INT(SQRT($W14)*(7/AB14)/12) & IF(MOD(INT(SQRT($W14)*(7/AB14)/4),3)=0, "", "+" & MOD(INT(SQRT($W14)*(7/AB14)/4),3)))) -> 3+1 | AI14: =IF((SQRT($W14)*(7/AC14))>=(SQRT($W14)),"-",IF(INT(SQRT($W14)*(7/AC14)/12)=0, MOD(INT(SQRT($W14)*(7/AC14)/4),3), INT(SQRT($W14)*(7/AC14)/12) & IF(MOD(INT(SQRT($W14)*(7/AC14)/4),3)=0, "", "+" & MOD(INT(SQRT($W14)*(7/AC14)/4),3)))) -> 4 | AJ14: =IF((SQRT($W14)*(7/AD14))>=(SQRT($W14)),"-",IF(INT(SQRT($W14)*(7/AD14)/12)=0, MOD(INT(SQRT($W14)*(7/AD14)/4),3), INT(SQRT($W14)*(7/AD14)/12) & IF(MOD(INT(SQRT($W14)*(7/AD14)/4),3)=0, "", "+" & MOD(INT(SQRT($W14)*(7/AD14)/4),3)))) -> 9 | AK14: 1982
A15: Armes à feu\Fusil Sniper | B15: Barrett - M82A2 Light-Fifty | C15: powder_projectiles | D15: powder_projectiles | F15: .50 BMG | G15: 12,7x99 | H15: 12.9 | I15: 29 | J15: 150 | K15: 300 | L15: 900 | M15: 1800 | N15: 2 | P15: 10 | Q15: SA | R15: 1 | S15: =VLOOKUP($F15,Munition!$B:$P,10,FALSE) -> 30 | T15: =VLOOKUP($F15,Munition!$B:$P,11,FALSE) -> 903 | U15: =T15 * POWER(I15/S15,0.25) -> 895.37907 | V15: =VLOOKUP($F15,Munition!$B:$P,5,FALSE) -> 42 | W15: =0.5 * (V15/1000) * (U15^2) -> 16835.777 | X15: =VLOOKUP($F15,Munition!$B:$P,15,FALSE) -> 331.55224 | Y15: =VLOOKUP($F15,Munition!$B:$P,9,FALSE) -> 1 | Z15: =VLOOKUP($F15,Munition!$B:$P,14,FALSE) -> 2.7156354e-05 | AA15: =0.0000001 * X15 * (2 * W15 / (V15/1000)) * Y15 -> 26.580665 | AB15: =0.0000001 * $X15 * (2 * $W15 * EXP(-(2*$Z15/($V15/1000)) * J15) / ($V15/1000)) * $Y15 -> 21.893945 | AC15: =0.0000001 * $X15 * (2 * $W15 * EXP(-(2*$Z15/($V15/1000)) * K15) / ($V15/1000)) * $Y15 -> 18.03359 | AD15: =0.0000001 * $X15 * (2 * $W15 * EXP(-(2*$Z15/($V15/1000)) * L15) / ($V15/1000)) * $Y15 -> 8.300704 | AE15: =0.0000001 * $X15 * (2 * $W15 * EXP(-(2*$Z15/($V15/1000)) * M15) / ($V15/1000)) * $Y15 -> 2.5921732 | AF15: =IF(INT(SQRT(W15)/12)=0, MOD(INT(SQRT(W15)/4),3), INT(SQRT(W15)/12) & "D6" & IF(MOD(INT(SQRT(W15)/4),3)=0, "", "+" & MOD(INT(SQRT(W15)/4),3))) -> 10D6+2 | AG15: =IF((SQRT($W15)*(7/AA15))>=(SQRT($W15)),"-",IF(INT(SQRT($W15)*(7/AA15)/12)=0, MOD(INT(SQRT($W15)*(7/AA15)/4),3), INT(SQRT($W15)*(7/AA15)/12) & IF(MOD(INT(SQRT($W15)*(7/AA15)/4),3)=0, "", "+" & MOD(INT(SQRT($W15)*(7/AA15)/4),3)))) -> 2+2 | AH15: =IF((SQRT($W15)*(7/AB15))>=(SQRT($W15)),"-",IF(INT(SQRT($W15)*(7/AB15)/12)=0, MOD(INT(SQRT($W15)*(7/AB15)/4),3), INT(SQRT($W15)*(7/AB15)/12) & IF(MOD(INT(SQRT($W15)*(7/AB15)/4),3)=0, "", "+" & MOD(INT(SQRT($W15)*(7/AB15)/4),3)))) -> 3+1 | AI15: =IF((SQRT($W15)*(7/AC15))>=(SQRT($W15)),"-",IF(INT(SQRT($W15)*(7/AC15)/12)=0, MOD(INT(SQRT($W15)*(7/AC15)/4),3), INT(SQRT($W15)*(7/AC15)/12) & IF(MOD(INT(SQRT($W15)*(7/AC15)/4),3)=0, "", "+" & MOD(INT(SQRT($W15)*(7/AC15)/4),3)))) -> 4 | AJ15: =IF((SQRT($W15)*(7/AD15))>=(SQRT($W15)),"-",IF(INT(SQRT($W15)*(7/AD15)/12)=0, MOD(INT(SQRT($W15)*(7/AD15)/4),3), INT(SQRT($W15)*(7/AD15)/12) & IF(MOD(INT(SQRT($W15)*(7/AD15)/4),3)=0, "", "+" & MOD(INT(SQRT($W15)*(7/AD15)/4),3)))) -> 9 | AK15: 1987
A16: Armes à feu\Fusil Sniper | B16: Barrett - M95 | C16: powder_projectiles | D16: powder_projectiles | F16: .50 BMG | G16: 12,7x99 | H16: 10 | I16: 29 | J16: 125 | K16: 250 | L16: 750 | M16: 1500 | N16: 2 | P16: 5 | Q16: BA | R16: 1 | S16: =VLOOKUP($F16,Munition!$B:$P,10,FALSE) -> 30 | T16: =VLOOKUP($F16,Munition!$B:$P,11,FALSE) -> 903 | U16: =T16 * POWER(I16/S16,0.25) -> 895.37907 | V16: =VLOOKUP($F16,Munition!$B:$P,5,FALSE) -> 42 | W16: =0.5 * (V16/1000) * (U16^2) -> 16835.777 | X16: =VLOOKUP($F16,Munition!$B:$P,15,FALSE) -> 331.55224 | Y16: =VLOOKUP($F16,Munition!$B:$P,9,FALSE) -> 1 | Z16: =VLOOKUP($F16,Munition!$B:$P,14,FALSE) -> 2.7156354e-05 | AA16: =0.0000001 * X16 * (2 * W16 / (V16/1000)) * Y16 -> 26.580665 | AB16: =0.0000001 * $X16 * (2 * $W16 * EXP(-(2*$Z16/($V16/1000)) * J16) / ($V16/1000)) * $Y16 -> 22.61332 | AC16: =0.0000001 * $X16 * (2 * $W16 * EXP(-(2*$Z16/($V16/1000)) * K16) / ($V16/1000)) * $Y16 -> 19.238128 | AD16: =0.0000001 * $X16 * (2 * $W16 * EXP(-(2*$Z16/($V16/1000)) * L16) / ($V16/1000)) * $Y16 -> 10.077591 | AE16: =0.0000001 * $X16 * (2 * $W16 * EXP(-(2*$Z16/($V16/1000)) * M16) / ($V16/1000)) * $Y16 -> 3.8207414 | AF16: =IF(INT(SQRT(W16)/12)=0, MOD(INT(SQRT(W16)/4),3), INT(SQRT(W16)/12) & "D6" & IF(MOD(INT(SQRT(W16)/4),3)=0, "", "+" & MOD(INT(SQRT(W16)/4),3))) -> 10D6+2 | AG16: =IF((SQRT($W16)*(7/AA16))>=(SQRT($W16)),"-",IF(INT(SQRT($W16)*(7/AA16)/12)=0, MOD(INT(SQRT($W16)*(7/AA16)/4),3), INT(SQRT($W16)*(7/AA16)/12) & IF(MOD(INT(SQRT($W16)*(7/AA16)/4),3)=0, "", "+" & MOD(INT(SQRT($W16)*(7/AA16)/4),3)))) -> 2+2 | AH16: =IF((SQRT($W16)*(7/AB16))>=(SQRT($W16)),"-",IF(INT(SQRT($W16)*(7/AB16)/12)=0, MOD(INT(SQRT($W16)*(7/AB16)/4),3), INT(SQRT($W16)*(7/AB16)/12) & IF(MOD(INT(SQRT($W16)*(7/AB16)/4),3)=0, "", "+" & MOD(INT(SQRT($W16)*(7/AB16)/4),3)))) -> 3+1 | AI16: =IF((SQRT($W16)*(7/AC16))>=(SQRT($W16)),"-",IF(INT(SQRT($W16)*(7/AC16)/12)=0, MOD(INT(SQRT($W16)*(7/AC16)/4),3), INT(SQRT($W16)*(7/AC16)/12) & IF(MOD(INT(SQRT($W16)*(7/AC16)/4),3)=0, "", "+" & MOD(INT(SQRT($W16)*(7/AC16)/4),3)))) -> 3+2 | AJ16: =IF((SQRT($W16)*(7/AD16))>=(SQRT($W16)),"-",IF(INT(SQRT($W16)*(7/AD16)/12)=0, MOD(INT(SQRT($W16)*(7/AD16)/4),3), INT(SQRT($W16)*(7/AD16)/12) & IF(MOD(INT(SQRT($W16)*(7/AD16)/4),3)=0, "", "+" & MOD(INT(SQRT($W16)*(7/AD16)/4),3)))) -> 7+1 | AK16: 1995
A17: Armes à feu\Fusil pompe | B17: Benelli - Benelli Supernova | C17: powder_projectiles | D17: powder_projectiles | F17: Cal. 12 G | G17: 18,5x70 | H17: 3.58 | I17: 20 | J17: 8 | K17: 16 | L17: 48 | M17: 96 | N17: 2 | P17: 5 | Q17: PA | R17: 1 | S17: =VLOOKUP($F17,Munition!$B:$P,10,FALSE) -> 20 | T17: =VLOOKUP($F17,Munition!$B:$P,11,FALSE) -> 408 | U17: =T17 * POWER(I17/S17,0.25) -> 408 | V17: =VLOOKUP($F17,Munition!$B:$P,5,FALSE) -> 38 | W17: =0.5 * (V17/1000) * (U17^2) -> 3162.816 | X17: =VLOOKUP($F17,Munition!$B:$P,15,FALSE) -> 141.36772 | Y17: =VLOOKUP($F17,Munition!$B:$P,9,FALSE) -> 1 | Z17: =VLOOKUP($F17,Munition!$B:$P,14,FALSE) -> 9.8784927e-05 | AA17: =0.0000001 * X17 * (2 * W17 / (V17/1000)) * Y17 -> 2.3532636 | AB17: =0.0000001 * $X17 * (2 * $W17 * EXP(-(2*$Z17/($V17/1000)) * J17) / ($V17/1000)) * $Y17 -> 2.2573905 | AC17: =0.0000001 * $X17 * (2 * $W17 * EXP(-(2*$Z17/($V17/1000)) * K17) / ($V17/1000)) * $Y17 -> 2.1654233 | AD17: =0.0000001 * $X17 * (2 * $W17 * EXP(-(2*$Z17/($V17/1000)) * L17) / ($V17/1000)) * $Y17 -> 1.8335266 | AE17: =0.0000001 * $X17 * (2 * $W17 * EXP(-(2*$Z17/($V17/1000)) * M17) / ($V17/1000)) * $Y17 -> 1.4285777 | AF17: =IF(INT(SQRT(W17)/12)=0, MOD(INT(SQRT(W17)/4),3), INT(SQRT(W17)/12) & "D6" & IF(MOD(INT(SQRT(W17)/4),3)=0, "", "+" & MOD(INT(SQRT(W17)/4),3))) -> 4D6+2 | AG17: =IF((SQRT($W17)*(7/AA17))>=(SQRT($W17)),"-",IF(INT(SQRT($W17)*(7/AA17)/12)=0, MOD(INT(SQRT($W17)*(7/AA17)/4),3), INT(SQRT($W17)*(7/AA17)/12) & IF(MOD(INT(SQRT($W17)*(7/AA17)/4),3)=0, "", "+" & MOD(INT(SQRT($W17)*(7/AA17)/4),3)))) -> - | AH17: =IF((SQRT($W17)*(7/AB17))>=(SQRT($W17)),"-",IF(INT(SQRT($W17)*(7/AB17)/12)=0, MOD(INT(SQRT($W17)*(7/AB17)/4),3), INT(SQRT($W17)*(7/AB17)/12) & IF(MOD(INT(SQRT($W17)*(7/AB17)/4),3)=0, "", "+" & MOD(INT(SQRT($W17)*(7/AB17)/4),3)))) -> - | AI17: =IF((SQRT($W17)*(7/AC17))>=(SQRT($W17)),"-",IF(INT(SQRT($W17)*(7/AC17)/12)=0, MOD(INT(SQRT($W17)*(7/AC17)/4),3), INT(SQRT($W17)*(7/AC17)/12) & IF(MOD(INT(SQRT($W17)*(7/AC17)/4),3)=0, "", "+" & MOD(INT(SQRT($W17)*(7/AC17)/4),3)))) -> - | AJ17: =IF((SQRT($W17)*(7/AD17))>=(SQRT($W17)),"-",IF(INT(SQRT($W17)*(7/AD17)/12)=0, MOD(INT(SQRT($W17)*(7/AD17)/4),3), INT(SQRT($W17)*(7/AD17)/12) & IF(MOD(INT(SQRT($W17)*(7/AD17)/4),3)=0, "", "+" & MOD(INT(SQRT($W17)*(7/AD17)/4),3)))) -> - | AK17: 2006
A18: Armes à feu\Fusil | B18: Benelli - M2 | C18: powder_projectiles | D18: powder_projectiles | F18: Cal. 12 G | G18: 18,5x70 | H18: 3.26 | I18: 20 | J18: 8 | K18: 16 | L18: 48 | M18: 96 | N18: 2 | P18: 7 | Q18: SA | R18: 1 | S18: =VLOOKUP($F18,Munition!$B:$P,10,FALSE) -> 20 | T18: =VLOOKUP($F18,Munition!$B:$P,11,FALSE) -> 408 | U18: =T18 * POWER(I18/S18,0.25) -> 408 | V18: =VLOOKUP($F18,Munition!$B:$P,5,FALSE) -> 38 | W18: =0.5 * (V18/1000) * (U18^2) -> 3162.816 | X18: =VLOOKUP($F18,Munition!$B:$P,15,FALSE) -> 141.36772 | Y18: =VLOOKUP($F18,Munition!$B:$P,9,FALSE) -> 1 | Z18: =VLOOKUP($F18,Munition!$B:$P,14,FALSE) -> 9.8784927e-05 | AA18: =0.0000001 * X18 * (2 * W18 / (V18/1000)) * Y18 -> 2.3532636 | AB18: =0.0000001 * $X18 * (2 * $W18 * EXP(-(2*$Z18/($V18/1000)) * J18) / ($V18/1000)) * $Y18 -> 2.2573905 | AC18: =0.0000001 * $X18 * (2 * $W18 * EXP(-(2*$Z18/($V18/1000)) * K18) / ($V18/1000)) * $Y18 -> 2.1654233 | AD18: =0.0000001 * $X18 * (2 * $W18 * EXP(-(2*$Z18/($V18/1000)) * L18) / ($V18/1000)) * $Y18 -> 1.8335266 | AE18: =0.0000001 * $X18 * (2 * $W18 * EXP(-(2*$Z18/($V18/1000)) * M18) / ($V18/1000)) * $Y18 -> 1.4285777 | AF18: =IF(INT(SQRT(W18)/12)=0, MOD(INT(SQRT(W18)/4),3), INT(SQRT(W18)/12) & "D6" & IF(MOD(INT(SQRT(W18)/4),3)=0, "", "+" & MOD(INT(SQRT(W18)/4),3))) -> 4D6+2 | AG18: =IF((SQRT($W18)*(7/AA18))>=(SQRT($W18)),"-",IF(INT(SQRT($W18)*(7/AA18)/12)=0, MOD(INT(SQRT($W18)*(7/AA18)/4),3), INT(SQRT($W18)*(7/AA18)/12) & IF(MOD(INT(SQRT($W18)*(7/AA18)/4),3)=0, "", "+" & MOD(INT(SQRT($W18)*(7/AA18)/4),3)))) -> - | AH18: =IF((SQRT($W18)*(7/AB18))>=(SQRT($W18)),"-",IF(INT(SQRT($W18)*(7/AB18)/12)=0, MOD(INT(SQRT($W18)*(7/AB18)/4),3), INT(SQRT($W18)*(7/AB18)/12) & IF(MOD(INT(SQRT($W18)*(7/AB18)/4),3)=0, "", "+" & MOD(INT(SQRT($W18)*(7/AB18)/4),3)))) -> - | AI18: =IF((SQRT($W18)*(7/AC18))>=(SQRT($W18)),"-",IF(INT(SQRT($W18)*(7/AC18)/12)=0, MOD(INT(SQRT($W18)*(7/AC18)/4),3), INT(SQRT($W18)*(7/AC18)/12) & IF(MOD(INT(SQRT($W18)*(7/AC18)/4),3)=0, "", "+" & MOD(INT(SQRT($W18)*(7/AC18)/4),3)))) -> - | AJ18: =IF((SQRT($W18)*(7/AD18))>=(SQRT($W18)),"-",IF(INT(SQRT($W18)*(7/AD18)/12)=0, MOD(INT(SQRT($W18)*(7/AD18)/4),3), INT(SQRT($W18)*(7/AD18)/12) & IF(MOD(INT(SQRT($W18)*(7/AD18)/4),3)=0, "", "+" & MOD(INT(SQRT($W18)*(7/AD18)/4),3)))) -> - | AK18: 1993
A19: Armes à feu\Fusil pompe | B19: Benelli - M3 | C19: powder_projectiles | D19: powder_projectiles | F19: Cal. 12 G | G19: 18,5x70 | H19: 3.24 | I19: 19 | J19: 8 | K19: 16 | L19: 48 | M19: 96 | N19: 2 | P19: 8 | Q19: PA/SA | R19: 1 | S19: =VLOOKUP($F19,Munition!$B:$P,10,FALSE) -> 20 | T19: =VLOOKUP($F19,Munition!$B:$P,11,FALSE) -> 408 | U19: =T19 * POWER(I19/S19,0.25) -> 402.80149 | V19: =VLOOKUP($F19,Munition!$B:$P,5,FALSE) -> 38 | W19: =0.5 * (V19/1000) * (U19^2) -> 3082.7317 | X19: =VLOOKUP($F19,Munition!$B:$P,15,FALSE) -> 141.36772 | Y19: =VLOOKUP($F19,Munition!$B:$P,9,FALSE) -> 1 | Z19: =VLOOKUP($F19,Munition!$B:$P,14,FALSE) -> 9.8784927e-05 | AA19: =0.0000001 * X19 * (2 * W19 / (V19/1000)) * Y19 -> 2.2936777 | AB19: =0.0000001 * $X19 * (2 * $W19 * EXP(-(2*$Z19/($V19/1000)) * J19) / ($V19/1000)) * $Y19 -> 2.2002321 | AC19: =0.0000001 * $X19 * (2 * $W19 * EXP(-(2*$Z19/($V19/1000)) * K19) / ($V19/1000)) * $Y19 -> 2.1105935 | AD19: =0.0000001 * $X19 * (2 * $W19 * EXP(-(2*$Z19/($V19/1000)) * L19) / ($V19/1000)) * $Y19 -> 1.7871007 | AE19: =0.0000001 * $X19 * (2 * $W19 * EXP(-(2*$Z19/($V19/1000)) * M19) / ($V19/1000)) * $Y19 -> 1.3924053 | AF19: =IF(INT(SQRT(W19)/12)=0, MOD(INT(SQRT(W19)/4),3), INT(SQRT(W19)/12) & "D6" & IF(MOD(INT(SQRT(W19)/4),3)=0, "", "+" & MOD(INT(SQRT(W19)/4),3))) -> 4D6+1 | AG19: =IF((SQRT($W19)*(7/AA19))>=(SQRT($W19)),"-",IF(INT(SQRT($W19)*(7/AA19)/12)=0, MOD(INT(SQRT($W19)*(7/AA19)/4),3), INT(SQRT($W19)*(7/AA19)/12) & IF(MOD(INT(SQRT($W19)*(7/AA19)/4),3)=0, "", "+" & MOD(INT(SQRT($W19)*(7/AA19)/4),3)))) -> - | AH19: =IF((SQRT($W19)*(7/AB19))>=(SQRT($W19)),"-",IF(INT(SQRT($W19)*(7/AB19)/12)=0, MOD(INT(SQRT($W19)*(7/AB19)/4),3), INT(SQRT($W19)*(7/AB19)/12) & IF(MOD(INT(SQRT($W19)*(7/AB19)/4),3)=0, "", "+" & MOD(INT(SQRT($W19)*(7/AB19)/4),3)))) -> - | AI19: =IF((SQRT($W19)*(7/AC19))>=(SQRT($W19)),"-",IF(INT(SQRT($W19)*(7/AC19)/12)=0, MOD(INT(SQRT($W19)*(7/AC19)/4),3), INT(SQRT($W19)*(7/AC19)/12) & IF(MOD(INT(SQRT($W19)*(7/AC19)/4),3)=0, "", "+" & MOD(INT(SQRT($W19)*(7/AC19)/4),3)))) -> - | AJ19: =IF((SQRT($W19)*(7/AD19))>=(SQRT($W19)),"-",IF(INT(SQRT($W19)*(7/AD19)/12)=0, MOD(INT(SQRT($W19)*(7/AD19)/4),3), INT(SQRT($W19)*(7/AD19)/12) & IF(MOD(INT(SQRT($W19)*(7/AD19)/4),3)=0, "", "+" & MOD(INT(SQRT($W19)*(7/AD19)/4),3)))) -> - | AK19: 1989
A20: Armes à feu\Fusil d'assaut | B20: Beretta - AR 70 | C20: powder_projectiles | D20: powder_projectiles | F20: 5,56 M193 | G20: 5,56x45 | H20: 3.545 | I20: 17.7 | J20: 66 | K20: 132 | L20: 396 | M20: 792 | N20: 2 | O20: 5 | P20: 30 | Q20: 1/55 | R20: 10 | S20: =VLOOKUP($F20,Munition!$B:$P,10,FALSE) -> 20 | T20: =VLOOKUP($F20,Munition!$B:$P,11,FALSE) -> 878 | U20: =T20 * POWER(I20/S20,0.25) -> 851.58957 | V20: =VLOOKUP($F20,Munition!$B:$P,5,FALSE) -> 3.56 | W20: =0.5 * (V20/1000) * (U20^2) -> 1290.8645 | X20: =VLOOKUP($F20,Munition!$B:$P,15,FALSE) -> 146.62585 | Y20: =VLOOKUP($F20,Munition!$B:$P,9,FALSE) -> 1 | Z20: =VLOOKUP($F20,Munition!$B:$P,14,FALSE) -> 3.7177961e-06 | AA20: =0.0000001 * X20 * (2 * W20 / (V20/1000)) * Y20 -> 10.633377 | AB20: =0.0000001 * $X20 * (2 * $W20 * EXP(-(2*$Z20/($V20/1000)) * J20) / ($V20/1000)) * $Y20 -> 9.264102 | AC20: =0.0000001 * $X20 * (2 * $W20 * EXP(-(2*$Z20/($V20/1000)) * K20) / ($V20/1000)) * $Y20 -> 8.0711508 | AD20: =0.0000001 * $X20 * (2 * $W20 * EXP(-(2*$Z20/($V20/1000)) * L20) / ($V20/1000)) * $Y20 -> 4.650118 | AE20: =0.0000001 * $X20 * (2 * $W20 * EXP(-(2*$Z20/($V20/1000)) * M20) / ($V20/1000)) * $Y20 -> 2.0335589 | AF20: =IF(INT(SQRT(W20)/12)=0, MOD(INT(SQRT(W20)/4),3), INT(SQRT(W20)/12) & "D6" & IF(MOD(INT(SQRT(W20)/4),3)=0, "", "+" & MOD(INT(SQRT(W20)/4),3))) -> 2D6+2 | AG20: =IF((SQRT($W20)*(7/AA20))>=(SQRT($W20)),"-",IF(INT(SQRT($W20)*(7/AA20)/12)=0, MOD(INT(SQRT($W20)*(7/AA20)/4),3), INT(SQRT($W20)*(7/AA20)/12) & IF(MOD(INT(SQRT($W20)*(7/AA20)/4),3)=0, "", "+" & MOD(INT(SQRT($W20)*(7/AA20)/4),3)))) -> 1+2 | AH20: =IF((SQRT($W20)*(7/AB20))>=(SQRT($W20)),"-",IF(INT(SQRT($W20)*(7/AB20)/12)=0, MOD(INT(SQRT($W20)*(7/AB20)/4),3), INT(SQRT($W20)*(7/AB20)/12) & IF(MOD(INT(SQRT($W20)*(7/AB20)/4),3)=0, "", "+" & MOD(INT(SQRT($W20)*(7/AB20)/4),3)))) -> 2 | AI20: =IF((SQRT($W20)*(7/AC20))>=(SQRT($W20)),"-",IF(INT(SQRT($W20)*(7/AC20)/12)=0, MOD(INT(SQRT($W20)*(7/AC20)/4),3), INT(SQRT($W20)*(7/AC20)/12) & IF(MOD(INT(SQRT($W20)*(7/AC20)/4),3)=0, "", "+" & MOD(INT(SQRT($W20)*(7/AC20)/4),3)))) -> 2+1 | AJ20: =IF((SQRT($W20)*(7/AD20))>=(SQRT($W20)),"-",IF(INT(SQRT($W20)*(7/AD20)/12)=0, MOD(INT(SQRT($W20)*(7/AD20)/4),3), INT(SQRT($W20)*(7/AD20)/12) & IF(MOD(INT(SQRT($W20)*(7/AD20)/4),3)=0, "", "+" & MOD(INT(SQRT($W20)*(7/AD20)/4),3)))) -> - | AK20: 1972
A21: Armes à feu\Pistolet auto | B21: beretta - Beretta 92FS | C21: powder_projectiles | D21: powder_projectiles | E21: Beretta 92FS | F21: 9 P | G21: 9x19 | H21: 0.975 | I21: 4.9 | J21: 8 | K21: 16 | L21: 48 | M21: 96 | N21: 3 | P21: 15 | Q21: SA | R21: 1 | S21: =VLOOKUP($F21,Munition!$B:$P,10,FALSE) -> 4.5 | T21: =VLOOKUP($F21,Munition!$B:$P,11,FALSE) -> 450 | U21: =T21 * POWER(I21/S21,0.25) -> 459.68296 | V21: =VLOOKUP($F21,Munition!$B:$P,5,FALSE) -> 6.75 | W21: =0.5 * (V21/1000) * (U21^2) -> 713.16593 | X21: =VLOOKUP($F21,Munition!$B:$P,15,FALSE) -> 106.1033 | Y21: =VLOOKUP($F21,Munition!$B:$P,9,FALSE) -> 1 | Z21: =VLOOKUP($F21,Munition!$B:$P,14,FALSE) -> 1.5586227e-05 | AA21: =0.0000001 * X21 * (2 * W21 / (V21/1000)) * Y21 -> 2.242052 | AB21: =0.0000001 * $X21 * (2 * $W21 * EXP(-(2*$Z21/($V21/1000)) * J21) / ($V21/1000)) * $Y21 -> 2.1607306 | AC21: =0.0000001 * $X21 * (2 * $W21 * EXP(-(2*$Z21/($V21/1000)) * K21) / ($V21/1000)) * $Y21 -> 2.0823587 | AD21: =0.0000001 * $X21 * (2 * $W21 * EXP(-(2*$Z21/($V21/1000)) * L21) / ($V21/1000)) * $Y21 -> 1.7962852 | AE21: =0.0000001 * $X21 * (2 * $W21 * EXP(-(2*$Z21/($V21/1000)) * M21) / ($V21/1000)) * $Y21 -> 1.4391461 | AF21: =IF(INT(SQRT(W21)/12)=0, MOD(INT(SQRT(W21)/4),3), INT(SQRT(W21)/12) & "D6" & IF(MOD(INT(SQRT(W21)/4),3)=0, "", "+" & MOD(INT(SQRT(W21)/4),3))) -> 2D6 | AG21: =IF((SQRT($W21)*(7/AA21))>=(SQRT($W21)),"-",IF(INT(SQRT($W21)*(7/AA21)/12)=0, MOD(INT(SQRT($W21)*(7/AA21)/4),3), INT(SQRT($W21)*(7/AA21)/12) & IF(MOD(INT(SQRT($W21)*(7/AA21)/4),3)=0, "", "+" & MOD(INT(SQRT($W21)*(7/AA21)/4),3)))) -> - | AH21: =IF((SQRT($W21)*(7/AB21))>=(SQRT($W21)),"-",IF(INT(SQRT($W21)*(7/AB21)/12)=0, MOD(INT(SQRT($W21)*(7/AB21)/4),3), INT(SQRT($W21)*(7/AB21)/12) & IF(MOD(INT(SQRT($W21)*(7/AB21)/4),3)=0, "", "+" & MOD(INT(SQRT($W21)*(7/AB21)/4),3)))) -> - | AI21: =IF((SQRT($W21)*(7/AC21))>=(SQRT($W21)),"-",IF(INT(SQRT($W21)*(7/AC21)/12)=0, MOD(INT(SQRT($W21)*(7/AC21)/4),3), INT(SQRT($W21)*(7/AC21)/12) & IF(MOD(INT(SQRT($W21)*(7/AC21)/4),3)=0, "", "+" & MOD(INT(SQRT($W21)*(7/AC21)/4),3)))) -> - | AJ21: =IF((SQRT($W21)*(7/AD21))>=(SQRT($W21)),"-",IF(INT(SQRT($W21)*(7/AD21)/12)=0, MOD(INT(SQRT($W21)*(7/AD21)/4),3), INT(SQRT($W21)*(7/AD21)/12) & IF(MOD(INT(SQRT($W21)*(7/AD21)/4),3)=0, "", "+" & MOD(INT(SQRT($W21)*(7/AD21)/4),3)))) -> - | AK21: 1976
